Workbook

Sheet README
A1: PROM06 TC01–TC12 Verified Results Matrix
A2: Built 13 Oct 2026 from: PR bot comments and run artifacts (PRs #46–#68 Condition C; PRs #70–#81 independent), experiment-metadata.json for 37 independent runs, local reproduction with Checkov 3.3.1 and tfsec 1.28.14, Ground-Truth Matrix v1.0 and Confluence PROM06-TC-Evidences v72 (13 Oct 10:47).
A3: Evidence hierarchy used: raw run artifacts > PR bot comments > Confluence/screenshots > draft matrix.
A4: Classification codes (target condition only):
A5: TP = target condition correctly reported FN = target condition not reported TN = no finding on a case with no intended weakness
A6: FP = finding that treats an acceptable configuration as a defect PARTIAL = reported inconsistently across runs CONTEXT = context-sensitive, researcher decision needed UNVERIFIED = evidence conflict, not usable
A7: AI (independent) = post-PR #69 workflow, scanner_findings_supplied_to_ai = false in every run's metadata, 3 successful runs per case (TC08: 3 successful + 1 failed). AI (hybrid) = earlier Condition C runs whose prompt contained normalised Checkov/tfsec findings.
A8: Severity labels are each tool's own scale and are not equivalent across tools (Checkov OSS JSON has no severity).
A9: Sheets: Verified Matrix · Summary (formula-driven counts) · Independent AI Runs · Scanner Results · Hybrid Runs (Condition C) · Decisions & Caveats · Draft Matrix (original).
A10: Decisions & Caveats: all ten proposed treatments agreed by AB on 13 Oct 2026; classifications in 'Verified Matrix' reflect them. Matrix frozen pending AI explanation/remediation scoring.
A12: Step 3 additions (13 Oct 2026):
A13: Metrics — case-level detection/false-alarm metrics for TC01–TC12 (verified) and TC01–TC15 (TC13–15 provisional), complementarity, AI run-level metrics, timing and remediation summaries (all formulas).
... A18: File name kept for continuity; the workbook now also covers TC13–TC15.

Sheet Verified Matrix
A1: Test case | B1: Scenario (Confluence v72) | C1: Ground truth (summary) | D1: Case type | E1: Checkov 3.3.1 observed | F1: Checkov class. | G1: tfsec 1.28.14 observed | H1: tfsec class. | I1: AI independent (3 runs) | J1: AI indep. class. | K1: AI hybrid / Condition C (earlier) | L1: AI hybrid class. | M1: Extra / unrelated findings | N1: Evidence references | O1: Caveats
A2: TC01 | B2: Secure baseline | C2: No intentional vulnerability (false-positive baseline). | D2: Secure | E2: 7 passed / 0 failed | F2: TN | G2: 0 findings | H2: TN | I2: 0 confirmed in 3/3 runs (100/100). Only FALSE_POSITIVE/INFORMATIONAL notes in the artifact. | J2: TN | K2: Conflicting: PR #46 (older fixture) 2 confirmed MEDIUM (TAG-001, LOG-001), 55/100; Confluence 'clean' screenshot from PR #55 cannot be tied to its own run. | L2: UNVERIFIED | M2: None confirmed. | N2: PR #70, 92ab884, runs 38404582550 / 38405003190 / 38405111880; hybrid PR #46, #55 | O2: Baseline evolved after PR #46 AI findings (tags, logging, deny rules) and prompt was adjusted — disclose as validity threat. TC01 rerun branch has a comment-only edit.
A3: TC02 | B3: Unrestricted SSH Access | C3: Inbound TCP/22 from 0.0.0.0/0 — genuine management-plane exposure. | D3: Vulnerable | E3: 7/0 — CKV_AZURE_10 evaluated and PASSED | F3: FN | G3: AVD-AZU-0047 + AVD-AZU-0050 (CRITICAL) | H3: TP | I3: HIGH SSH finding in 3/3 runs (70/100). | J3: TP | K3: CRITICAL SSH, cited tfsec IDs (PR #56). | L3: TP | M3: tfsec: 2 rules for one condition (normalise to 1). | N3: PR #71, 3eda6f7; hybrid PR #56 | O3: Checkov passes because '0.0.0.0/0' is not matched as internet; CKV_AZURE_10 fails when the source is '*' (local probe).
A4: TC03 | B4: Unrestricted RDP Access | C4: Inbound TCP/3389 from 0.0.0.0/0 — genuine management-plane exposure. | D4: Vulnerable | E4: 7/0 — CKV_AZURE_9 evaluated and PASSED | F4: FN | G4: AVD-AZU-0048 + AVD-AZU-0047 (CRITICAL) | H4: TP | I4: HIGH RDP finding in 3/3 runs; run 3 added a duplicate SEC-001 policy finding (40/100). | J4: TP | K4: CRITICAL RDP, cited tfsec IDs (PR #57). | L4: TP | M4: AI run 3: duplicate SEC-001 finding for the same condition; tfsec: 2 rules, 1 condition. | N4: PR #72, 27789d9; hybrid PR #57 | O4: Same Checkov source-matching behaviour as TC02 (inferred; probe run on TC02 only).
A5: TC04 | B5: Public HTTP Ingress | C5: Inbound TCP/80 from 0.0.0.0/0 — intended TC04 weakness (Confluence v72). | D5: Vulnerable | E5: 7/0 — CKV_AZURE_160 evaluated and PASSED | F5: FN | G5: AVD-AZU-0047 (CRITICAL, generic public ingress) | H5: TP | I5: HIGH HTTP finding in 3/3 runs (70/100). | J5: TP | K5: HIGH HTTP, cited tfsec ID (PR #58). | L5: TP | M5: — | N5: PR #73, cbc6855; hybrid PR #58 | O5: GT v1.0 described TC04 as context-dependent; Confluence v72 fixes it as an intended weakness. tfsec rule is not port-specific.
A6: TC05 | B6: Missing NSG Association | C6: NSG exists but is not associated with the subnet — control not effective. | D6: Vulnerable | E6: CKV2_AZURE_31 (6 passed / 1 failed) | F6: TP | G6: 0 findings | H6: FN | I6: NET-001 finding in 3/3 runs (HIGH, HIGH, MEDIUM). | J6: TP | K6: MEDIUM NET-001, cited Checkov ID (PR #59). | L6: TP | M6: AI: NEEDS_CONTEXT note in every run about the stale 'Custom resolver' DNS comment (fixture artefact). | N6: PR #74, 14486bd; hybrid PR #59 | O6: Severity varied across identical runs.
A7: TC06 | B7: Public DNS Configuration | C7: VNet uses public resolver 8.8.8.8 contrary to NET-002 / CKV_AZURE_183. | D7: Vulnerable | E7: CKV_AZURE_183 + CKV_AZURE_182 (5/2) | F7: TP | G7: 0 findings | H7: FN | I7: MEDIUM NET-002 finding in 3/3 runs (85/100). | J7: TP | K7: MEDIUM NET-002, cited Checkov IDs (PR #61). | L7: TP | M7: Checkov CKV_AZURE_182 (≥2 DNS endpoints) is related but not the target condition. | N7: PR #75, eb51ee9; hybrid PR #61 | O7: Ground truth depends on the project baseline (NET-002); public DNS is not inherently insecure.
A8: TC07 | B8: Weak TLS Configuration | C8: Storage account min_tls_version = TLS1_0 below TLS 1.2 minimum. | D8: Vulnerable | E8: CKV_AZURE_44 among 11 failed (11/11) | F8: TP | G8: AVD-AZU-0011 (CRITICAL) | H8: TP | I8: HIGH TLS finding in 3/3 runs + LOW TAG-001 (65/100). | J8: TP | K8: CRITICAL TLS + 2 extra findings (PR #63). | L8: TP | M8: Checkov: 10 unrelated storage checks fail. AI: valid LOW TAG-001 (storage is taggable) + NEEDS_CONTEXT public access. | N8: PR #76, b6e93b7; hybrid PR #63 | O8: Fixture not single-variable (new storage account, hard-coded RG, non-standard tags); Confluence scenario said TC12 HTTPS service would be reused.
A9: TC08 | B9: Missing Diagnostic/Audit Logging | C9: NSG diagnostic setting removed; logs not forwarded to Log Analytics (LOG-001). | D9: Vulnerable | E9: 7/0 | F9: FN | G9: 0 findings | H9: FN | I9: Raised in all 4 runs but classified inconsistently: FALSE_POSITIVE (output rejected, run failed), NEEDS_CONTEXT ×2, CONFIRMED ×1. | J9: PARTIAL | K9: MEDIUM LOG-001 confirmed (PR #64). | L9: TP | M9: — | N9: PR #77, c86e4d5, runs 38404605125 (failed) / 38405066857 / 38405174844 / 38405218950; hybrid PR #64 | O9: Only the AI is given LOG-001; failed run's summary wrongly claimed the absence was intentional.
A10: TC09 | B10: Plaintext Credentials (dummy) | C10: Dummy credential-shaped string hard-coded in a Terraform local; value is non-sensitive test data. | D10: Vulnerable | E10: 7/0 (Checkov run with --framework terraform; secrets framework not run) | F10: FN | G10: 0 findings | H10: FN | I10: MEDIUM hard-coded secret finding in 3/3 runs (85/100). | J10: TP | K10: MEDIUM finding (PR #65). | L10: TP | M10: — | N10: PR #78, 277a730; hybrid PR #65 | O10: Checkov non-detection reflects pipeline configuration as much as tool capability. Explanation accuracy (state claims) to be scored in step 2.
A11: TC10 | B11: Excessive Azure IAM Permissions | C11: Custom role actions = ['*'] at subscription scope exceeds minimum. | D11: Vulnerable | E11: CKV_AZURE_39 (7/1) | F11: TP | G11: 0 findings | H11: FN | I11: HIGH wildcard-role finding in 3/3 runs; 2/3 runs added LOW TAG-001. | J11: TP | K11: Run 1: 2 × CRITICAL (40/100); rerun same commit: 1 × HIGH (70/100) (PR #66). | L11: TP | M11: AI TAG-001 on azurerm_role_definition (resource has no tags) — AI false positive in 2/3 runs. | N11: PR #79, bd8a61f; hybrid PR #66 (2 attempts) | O11: Matrix 'critical' reflected hybrid run 1 only.
A12: TC11 | B12: Multi-file, context-dependent weakness | C12: Wildcard role vs read-only actions documented in tc11_requirements.tf. | D12: Vulnerable | E12: CKV_AZURE_39 (7/1) | F12: TP | G12: 0 findings | H12: FN | I12: HIGH finding in 3/3 runs; all 3 cite tc11_requirements.tf. | J12: TP | K12: HIGH finding ×2, cited Checkov (PR #67). | L12: TP | M12: — | N12: PR #80, 3dd9a04; hybrid PR #67 (2 attempts) | O12: Construct validity: the wildcard alone triggers detection, so this does not isolate multi-file reasoning. Confluence heading 'AI-only (B)' is wrong — evidence is Condition C.
A13: TC12 | B13: Legitimate Public HTTPS Service | C13: Public TCP/443 is intentional; exposure alone is not a vulnerability. | D13: Legitimate | E13: 11 passed / 0 failed | F13: TN | G13: AVD-AZU-0047 (CRITICAL) on the intended rule | H13: CONTEXT | I13: Varied: run 1 blocked (HIGH + MEDIUM SEC-001 + LOW TAG-001, 50/100); run 2 LOW TAG-001 only (95); run 3 none (100), said SEC-001 justified and TAG-001 n/a. | J13: CONTEXT | K13: MEDIUM SEC-001 scope concern (PR #68). | L13: CONTEXT | M13: AI TAG-001 on azurerm_network_security_rule (resource has no tags) — AI false positive in 2/3 runs. | N13: PR #81, 9cee1fe; hybrid PR #68 | O13: Decide whether the shared-NSG/wildcard-destination scope concern counts as a separate weakness; until then tfsec and AI are CONTEXT.

Sheet Summary
A1: Descriptive counts (formula-driven from 'Verified Matrix')
A3: Measure | B3: Checkov | C3: tfsec | D3: AI independent | E3: AI hybrid (Cond. C) | F3: Definition / denominator
A4: Vulnerable cases (denominator) | B4: =COUNTIF('Verified Matrix'!$D$2:$D$13,"Vulnerable") -> 10 | C4: =COUNTIF('Verified Matrix'!$D$2:$D$13,"Vulnerable") -> 10 | D4: =COUNTIF('Verified Matrix'!$D$2:$D$13,"Vulnerable") -> 10 | E4: =COUNTIF('Verified Matrix'!$D$2:$D$13,"Vulnerable") -> 10 | F4: TC02–TC11
A5: Target condition detected (TP) | B5: =COUNTIFS('Verified Matrix'!$D$2:$D$13,"Vulnerable",'Verified Matrix'!$F$2:$F$13,"TP") -> 5 | C5: =COUNTIFS('Verified Matrix'!$D$2:$D$13,"Vulnerable",'Verified Matrix'!$H$2:$H$13,"TP") -> 4 | D5: =COUNTIFS('Verified Matrix'!$D$2:$D$13,"Vulnerable",'Verified Matrix'!$J$2:$J$13,"TP") -> 9 | E5: =COUNTIFS('Verified Matrix'!$D$2:$D$13,"Vulnerable",'Verified Matrix'!$L$2:$L$13,"TP") -> 10 | F5: Normalised: one detection per case regardless of rule count
A6: Target condition missed (FN) | B6: =COUNTIFS('Verified Matrix'!$D$2:$D$13,"Vulnerable",'Verified Matrix'!$F$2:$F$13,"FN") -> 5 | C6: =COUNTIFS('Verified Matrix'!$D$2:$D$13,"Vulnerable",'Verified Matrix'!$H$2:$H$13,"FN") -> 6 | D6: =COUNTIFS('Verified Matrix'!$D$2:$D$13,"Vulnerable",'Verified Matrix'!$J$2:$J$13,"FN") -> 0 | E6: =COUNTIFS('Verified Matrix'!$D$2:$D$13,"Vulnerable",'Verified Matrix'!$L$2:$L$13,"FN") -> 0
A7: Inconsistent across runs (PARTIAL) | B7: =COUNTIFS('Verified Matrix'!$D$2:$D$13,"Vulnerable",'Verified Matrix'!$F$2:$F$13,"PARTIAL") -> 0 | C7: =COUNTIFS('Verified Matrix'!$D$2:$D$13,"Vulnerable",'Verified Matrix'!$H$2:$H$13,"PARTIAL") -> 0 | D7: =COUNTIFS('Verified Matrix'!$D$2:$D$13,"Vulnerable",'Verified Matrix'!$J$2:$J$13,"PARTIAL") -> 1 | E7: =COUNTIFS('Verified Matrix'!$D$2:$D$13,"Vulnerable",'Verified Matrix'!$L$2:$L$13,"PARTIAL") -> 0 | F7: AI only: TC08
A8: Detection rate (TP / vulnerable cases) | B8: =IFERROR(B5/B4,0) -> 0.5 | C8: =IFERROR(C5/C4,0) -> 0.4 | D8: =IFERROR(D5/D4,0) -> 0.9 | E8: =IFERROR(E5/E4,0) -> 1 | F8: Descriptive only; n = 10 constructed cases, not a population estimate
A9: Secure baseline TC01 — clean (TN) | B9: =COUNTIFS('Verified Matrix'!$D$2:$D$13,"Secure",'Verified Matrix'!$F$2:$F$13,"TN") -> 1 | C9: =COUNTIFS('Verified Matrix'!$D$2:$D$13,"Secure",'Verified Matrix'!$H$2:$H$13,"TN") -> 1 | D9: =COUNTIFS('Verified Matrix'!$D$2:$D$13,"Secure",'Verified Matrix'!$J$2:$J$13,"TN") -> 1 | E9: =COUNTIFS('Verified Matrix'!$D$2:$D$13,"Secure",'Verified Matrix'!$L$2:$L$13,"TN") -> 0 | F9: 1 case
A10: Secure baseline TC01 — unverified | B10: =COUNTIFS('Verified Matrix'!$D$2:$D$13,"Secure",'Verified Matrix'!$F$2:$F$13,"UNVERIFIED") -> 0 | C10: =COUNTIFS('Verified Matrix'!$D$2:$D$13,"Secure",'Verified Matrix'!$H$2:$H$13,"UNVERIFIED") -> 0 | D10: =COUNTIFS('Verified Matrix'!$D$2:$D$13,"Secure",'Verified Matrix'!$J$2:$J$13,"UNVERIFIED") -> 0 | E10: =COUNTIFS('Verified Matrix'!$D$2:$D$13,"Secure",'Verified Matrix'!$L$2:$L$13,"UNVERIFIED") -> 1 | F10: Hybrid TC01 evidence conflict
A11: Legitimate TC12 — no finding (TN) | B11: =COUNTIFS('Verified Matrix'!$D$2:$D$13,"Legitimate",'Verified Matrix'!$F$2:$F$13,"TN") -> 1 | C11: =COUNTIFS('Verified Matrix'!$D$2:$D$13,"Legitimate",'Verified Matrix'!$H$2:$H$13,"TN") -> 0 | D11: =COUNTIFS('Verified Matrix'!$D$2:$D$13,"Legitimate",'Verified Matrix'!$J$2:$J$13,"TN") -> 0 | E11: =COUNTIFS('Verified Matrix'!$D$2:$D$13,"Legitimate",'Verified Matrix'!$L$2:$L$13,"TN") -> 0 | F11: 1 case
A12: Legitimate TC12 — context-sensitive (CONTEXT) | B12: =COUNTIFS('Verified Matrix'!$D$2:$D$13,"Legitimate",'Verified Matrix'!$F$2:$F$13,"CONTEXT") -> 0 | C12: =COUNTIFS('Verified Matrix'!$D$2:$D$13,"Legitimate",'Verified Matrix'!$H$2:$H$13,"CONTEXT") -> 1 | D12: =COUNTIFS('Verified Matrix'!$D$2:$D$13,"Legitimate",'Verified Matrix'!$J$2:$J$13,"CONTEXT") -> 1 | E12: =COUNTIFS('Verified Matrix'!$D$2:$D$13,"Legitimate",'Verified Matrix'!$L$2:$L$13,"CONTEXT") -> 1 | F12: Agreed 13 Oct: report both readings (D2)
A15: Union and overlap (vulnerable cases)
A16: Detected by Checkov OR tfsec | B16: =SUMPRODUCT(('Verified Matrix'!$D$2:$D$13="Vulnerable")*((('Verified Matrix'!$F$2:$F$13="TP")+('Verified Matrix'!$H$2:$H$13="TP"))>0)) -> 8 | F16: Scanner union
A17: Detected by AI independent (TP) but by neither scanner | B17: =SUMPRODUCT(('Verified Matrix'!$D$2:$D$13="Vulnerable")*('Verified Matrix'!$J$2:$J$13="TP")*('Verified Matrix'!$F$2:$F$13<>"TP")*('Verified Matrix'!$H$2:$H$13<>"TP")) -> 1 | F17: TC09 (TC08 is PARTIAL)
A18: Detected by a scanner but not by AI independent (TP) | B18: =SUMPRODUCT(('Verified Matrix'!$D$2:$D$13="Vulnerable")*(((('Verified Matrix'!$F$2:$F$13="TP")+('Verified Matrix'!$H$2:$H$13="TP"))>0))*('Verified Matrix'!$J$2:$J$13<>"TP")) -> 0 | F18: None expected
A19: Missed by all three | B19: =SUMPRODUCT(('Verified Matrix'!$D$2:$D$13="Vulnerable")*('Verified Matrix'!$F$2:$F$13<>"TP")*('Verified Matrix'!$H$2:$H$13<>"TP")*('Verified Matrix'!$J$2:$J$13<>"TP")*('Verified Matrix'!$J$2:$J$13<>"PARTIAL")) -> 0
A21: Notes: counts are descriptive for 12 controlled fixtures. Alert counts are not quality measures; scanner rules for one condition are normalised to one detection. AI independent classification uses 3 identical runs per case.

Sheet Metrics
A1: Step 3 metrics — detection, false alarms, run consistency, timing and remediation
A2: Case-level classes for TC01–TC12 are linked from 'Verified Matrix' (green). TC13–TC15 are typed (blue) from local scans and the nine run artefacts (metadata verified: INDEPENDENT, no scanner input). All rates are descriptive for constructed cases (n = 15), not population estimates.
A4: TC | B4: Case type | C4: Checkov | D4: tfsec | E4: Scanner union | F4: AI independent | G4: Status | H4: Note
A5: ='Verified Matrix'!A2 -> TC01 | B5: ='Verified Matrix'!D2 -> Secure | C5: ='Verified Matrix'!F2 -> TN | D5: ='Verified Matrix'!H2 -> TN | E5: =IF(OR(C5="TP",D5="TP"),"TP",IF(B5="Vulnerable","FN",IF(OR(C5="CONTEXT",D5="CONTEXT"),"CONTEXT",IF(OR(C5="FP",D5="FP"),"FP","TN")))) -> TN | F5: ='Verified Matrix'!J2 -> TN | G5: Verified | H5: Secure baseline.
A6: ='Verified Matrix'!A3 -> TC02 | B6: ='Verified Matrix'!D3 -> Vulnerable | C6: ='Verified Matrix'!F3 -> FN | D6: ='Verified Matrix'!H3 -> TP | E6: =IF(OR(C6="TP",D6="TP"),"TP",IF(B6="Vulnerable","FN",IF(OR(C6="CONTEXT",D6="CONTEXT"),"CONTEXT",IF(OR(C6="FP",D6="FP"),"FP","TN")))) -> TP | F6: ='Verified Matrix'!J3 -> TP | G6: Verified
A7: ='Verified Matrix'!A4 -> TC03 | B7: ='Verified Matrix'!D4 -> Vulnerable | C7: ='Verified Matrix'!F4 -> FN | D7: ='Verified Matrix'!H4 -> TP | E7: =IF(OR(C7="TP",D7="TP"),"TP",IF(B7="Vulnerable","FN",IF(OR(C7="CONTEXT",D7="CONTEXT"),"CONTEXT",IF(OR(C7="FP",D7="FP"),"FP","TN")))) -> TP | F7: ='Verified Matrix'!J4 -> TP | G7: Verified
A8: ='Verified Matrix'!A5 -> TC04 | B8: ='Verified Matrix'!D5 -> Vulnerable | C8: ='Verified Matrix'!F5 -> FN | D8: ='Verified Matrix'!H5 -> TP | E8: =IF(OR(C8="TP",D8="TP"),"TP",IF(B8="Vulnerable","FN",IF(OR(C8="CONTEXT",D8="CONTEXT"),"CONTEXT",IF(OR(C8="FP",D8="FP"),"FP","TN")))) -> TP | F8: ='Verified Matrix'!J5 -> TP | G8: Verified
A9: ='Verified Matrix'!A6 -> TC05 | B9: ='Verified Matrix'!D6 -> Vulnerable | C9: ='Verified Matrix'!F6 -> TP | D9: ='Verified Matrix'!H6 -> FN | E9: =IF(OR(C9="TP",D9="TP"),"TP",IF(B9="Vulnerable","FN",IF(OR(C9="CONTEXT",D9="CONTEXT"),"CONTEXT",IF(OR(C9="FP",D9="FP"),"FP","TN")))) -> TP | F9: ='Verified Matrix'!J6 -> TP | G9: Verified
A10: ='Verified Matrix'!A7 -> TC06 | B10: ='Verified Matrix'!D7 -> Vulnerable | C10: ='Verified Matrix'!F7 -> TP | D10: ='Verified Matrix'!H7 -> FN | E10: =IF(OR(C10="TP",D10="TP"),"TP",IF(B10="Vulnerable","FN",IF(OR(C10="CONTEXT",D10="CONTEXT"),"CONTEXT",IF(OR(C10="FP",D10="FP"),"FP","TN")))) -> TP | F10: ='Verified Matrix'!J7 -> TP | G10: Verified
A11: ='Verified Matrix'!A8 -> TC07 | B11: ='Verified Matrix'!D8 -> Vulnerable | C11: ='Verified Matrix'!F8 -> TP | D11: ='Verified Matrix'!H8 -> TP | E11: =IF(OR(C11="TP",D11="TP"),"TP",IF(B11="Vulnerable","FN",IF(OR(C11="CONTEXT",D11="CONTEXT"),"CONTEXT",IF(OR(C11="FP",D11="FP"),"FP","TN")))) -> TP | F11: ='Verified Matrix'!J8 -> TP | G11: Verified
A12: ='Verified Matrix'!A9 -> TC08 | B12: ='Verified Matrix'!D9 -> Vulnerable | C12: ='Verified Matrix'!F9 -> FN | D12: ='Verified Matrix'!H9 -> FN | E12: =IF(OR(C12="TP",D12="TP"),"TP",IF(B12="Vulnerable","FN",IF(OR(C12="CONTEXT",D12="CONTEXT"),"CONTEXT",IF(OR(C12="FP",D12="FP"),"FP","TN")))) -> FN | F12: ='Verified Matrix'!J9 -> PARTIAL | G12: Verified | H12: Raised 4/4 runs, confirmed 1/4 (PARTIAL).
A13: ='Verified Matrix'!A10 -> TC09 | B13: ='Verified Matrix'!D10 -> Vulnerable | C13: ='Verified Matrix'!F10 -> FN | D13: ='Verified Matrix'!H10 -> FN | E13: =IF(OR(C13="TP",D13="TP"),"TP",IF(B13="Vulnerable","FN",IF(OR(C13="CONTEXT",D13="CONTEXT"),"CONTEXT",IF(OR(C13="FP",D13="FP"),"FP","TN")))) -> FN | F13: ='Verified Matrix'!J10 -> TP | G13: Verified | H13: Only the AI detected it (scanners FN).
A14: ='Verified Matrix'!A11 -> TC10 | B14: ='Verified Matrix'!D11 -> Vulnerable | C14: ='Verified Matrix'!F11 -> TP | D14: ='Verified Matrix'!H11 -> FN | E14: =IF(OR(C14="TP",D14="TP"),"TP",IF(B14="Vulnerable","FN",IF(OR(C14="CONTEXT",D14="CONTEXT"),"CONTEXT",IF(OR(C14="FP",D14="FP"),"FP","TN")))) -> TP | F14: ='Verified Matrix'!J11 -> TP | G14: Verified
A15: ='Verified Matrix'!A12 -> TC11 | B15: ='Verified Matrix'!D12 -> Vulnerable | C15: ='Verified Matrix'!F12 -> TP | D15: ='Verified Matrix'!H12 -> FN | E15: =IF(OR(C15="TP",D15="TP"),"TP",IF(B15="Vulnerable","FN",IF(OR(C15="CONTEXT",D15="CONTEXT"),"CONTEXT",IF(OR(C15="FP",D15="FP"),"FP","TN")))) -> TP | F15: ='Verified Matrix'!J12 -> TP | G15: Verified | H15: Construct not isolated: CKV_AZURE_39 fires on the wildcard alone.
A16: ='Verified Matrix'!A13 -> TC12 | B16: ='Verified Matrix'!D13 -> Legitimate | C16: ='Verified Matrix'!F13 -> TN | D16: ='Verified Matrix'!H13 -> CONTEXT | E16: =IF(OR(C16="TP",D16="TP"),"TP",IF(B16="Vulnerable","FN",IF(OR(C16="CONTEXT",D16="CONTEXT"),"CONTEXT",IF(OR(C16="FP",D16="FP"),"FP","TN")))) -> CONTEXT | F16: ='Verified Matrix'!J13 -> CONTEXT | G16: Verified | H16: Report both readings (decision D2).
A17: TC13 | B17: Vulnerable | C17: FN | D17: FN | E17: =IF(OR(C17="TP",D17="TP"),"TP",IF(B17="Vulnerable","FN",IF(OR(C17="CONTEXT",D17="CONTEXT"),"CONTEXT",IF(OR(C17="FP",D17="FP"),"FP","TN")))) -> FN | F17: TP | G17: Verified | H17: Contributor at subscription vs documented Reader-on-RG need. Checkov 7/0, tfsec 0; AI HIGH 3/3.
A18: TC14 | B18: Secure | C18: TN | D18: TN | E18: =IF(OR(C18="TP",D18="TP"),"TP",IF(B18="Vulnerable","FN",IF(OR(C18="CONTEXT",D18="CONTEXT"),"CONTEXT",IF(OR(C18="FP",D18="FP"),"FP","TN")))) -> TN | F18: TN | G18: Verified | H18: Restricted SSH (remediated TC02). AI: LOW wildcard-destination finding confirmed in run 1; runs 2–3 clean with NEEDS_CONTEXT bastion notes (hidden from PR comment).
A19: TC15 | B19: Vulnerable | C19: FN | D19: FN | E19: =IF(OR(C19="TP",D19="TP"),"TP",IF(B19="Vulnerable","FN",IF(OR(C19="CONTEXT",D19="CONTEXT"),"CONTEXT",IF(OR(C19="FP",D19="FP"),"FP","TN")))) -> FN | F19: TP | G19: Verified | H19: Hard-coded password in variable default. Checkov 7/0 (secrets framework not run), tfsec 0; AI HIGH 3/3.
A22: A. Case level — TC01–TC12 (verified)
A23: Measure | C23: Checkov | D23: tfsec | E23: Scanner union | F23: AI independent | H23: Definition
A24: Vulnerable cases | C24: =COUNTIF($B$5:$B$16,"Vulnerable") -> 10 | D24: =COUNTIF($B$5:$B$16,"Vulnerable") -> 10 | E24: =COUNTIF($B$5:$B$16,"Vulnerable") -> 10 | F24: =COUNTIF($B$5:$B$16,"Vulnerable") -> 10 | H24: Denominator for detection rate
A25: Detected (TP) | C25: =COUNTIFS($B$5:$B$16,"Vulnerable",C$5:C$16,"TP") -> 5 | D25: =COUNTIFS($B$5:$B$16,"Vulnerable",D$5:D$16,"TP") -> 4 | E25: =COUNTIFS($B$5:$B$16,"Vulnerable",E$5:E$16,"TP") -> 8 | F25: =COUNTIFS($B$5:$B$16,"Vulnerable",F$5:F$16,"TP") -> 9 | H25: One detection per case regardless of rule count
A26: Partial (raised, not consistently confirmed) | C26: =COUNTIFS($B$5:$B$16,"Vulnerable",C$5:C$16,"PARTIAL") -> 0 | D26: =COUNTIFS($B$5:$B$16,"Vulnerable",D$5:D$16,"PARTIAL") -> 0 | E26: =COUNTIFS($B$5:$B$16,"Vulnerable",E$5:E$16,"PARTIAL") -> 0 | F26: =COUNTIFS($B$5:$B$16,"Vulnerable",F$5:F$16,"PARTIAL") -> 1 | H26: AI TC08
A27: Missed (FN) | C27: =COUNTIFS($B$5:$B$16,"Vulnerable",C$5:C$16,"FN") -> 5 | D27: =COUNTIFS($B$5:$B$16,"Vulnerable",D$5:D$16,"FN") -> 6 | E27: =COUNTIFS($B$5:$B$16,"Vulnerable",E$5:E$16,"FN") -> 2 | F27: =COUNTIFS($B$5:$B$16,"Vulnerable",F$5:F$16,"FN") -> 0
A28: Detection rate, strict (TP ÷ vulnerable) | C28: =IFERROR(C25/C24,0) -> 0.5 | D28: =IFERROR(D25/D24,0) -> 0.4 | E28: =IFERROR(E25/E24,0) -> 0.8 | F28: =IFERROR(F25/F24,0) -> 0.9 | H28: PARTIAL counted as miss
A29: Detection rate, lenient ((TP + PARTIAL) ÷ vulnerable) | C29: =IFERROR((C25+C26)/C24,0) -> 0.5 | D29: =IFERROR((D25+D26)/D24,0) -> 0.4 | E29: =IFERROR((E25+E26)/E24,0) -> 0.8 | F29: =IFERROR((F25+F26)/F24,0) -> 1 | H29: PARTIAL counted as hit
A30: Non-vulnerable cases (secure + legitimate) | C30: =COUNTIF($B$5:$B$16,"<>Vulnerable") -> 2 | D30: =COUNTIF($B$5:$B$16,"<>Vulnerable") -> 2 | E30: =COUNTIF($B$5:$B$16,"<>Vulnerable") -> 2 | F30: =COUNTIF($B$5:$B$16,"<>Vulnerable") -> 2 | H30: TC01, TC12 (+TC14)
A31: Clean on non-vulnerable (TN) | C31: =COUNTIFS($B$5:$B$16,"<>Vulnerable",C$5:C$16,"TN") -> 2 | D31: =COUNTIFS($B$5:$B$16,"<>Vulnerable",D$5:D$16,"TN") -> 1 | E31: =COUNTIFS($B$5:$B$16,"<>Vulnerable",E$5:E$16,"TN") -> 1 | F31: =COUNTIFS($B$5:$B$16,"<>Vulnerable",F$5:F$16,"TN") -> 1
A32: Flagged non-vulnerable (FP or CONTEXT) | C32: =COUNTIFS($B$5:$B$16,"<>Vulnerable",C$5:C$16,"FP")+COUNTIFS($B$5:$B$16,"<>Vulnerable",C$5:C$16,"CONTEXT") -> 0 | D32: =COUNTIFS($B$5:$B$16,"<>Vulnerable",D$5:D$16,"FP")+COUNTIFS($B$5:$B$16,"<>Vulnerable",D$5:D$16,"CONTEXT") -> 1 | E32: =COUNTIFS($B$5:$B$16,"<>Vulnerable",E$5:E$16,"FP")+COUNTIFS($B$5:$B$16,"<>Vulnerable",E$5:E$16,"CONTEXT") -> 1 | F32: =COUNTIFS($B$5:$B$16,"<>Vulnerable",F$5:F$16,"FP")+COUNTIFS($B$5:$B$16,"<>Vulnerable",F$5:F$16,"CONTEXT") -> 1 | H32: TC12 counted here for tfsec and AI
A35: B. Case level — TC01–TC15
A36: Measure | C36: Checkov | D36: tfsec | E36: Scanner union | F36: AI independent | H36: Definition
A37: Vulnerable cases | C37: =COUNTIF($B$5:$B$19,"Vulnerable") -> 12 | D37: =COUNTIF($B$5:$B$19,"Vulnerable") -> 12 | E37: =COUNTIF($B$5:$B$19,"Vulnerable") -> 12 | F37: =COUNTIF($B$5:$B$19,"Vulnerable") -> 12 | H37: Denominator for detection rate
A38: Detected (TP) | C38: =COUNTIFS($B$5:$B$19,"Vulnerable",C$5:C$19,"TP") -> 5 | D38: =COUNTIFS($B$5:$B$19,"Vulnerable",D$5:D$19,"TP") -> 4 | E38: =COUNTIFS($B$5:$B$19,"Vulnerable",E$5:E$19,"TP") -> 8 | F38: =COUNTIFS($B$5:$B$19,"Vulnerable",F$5:F$19,"TP") -> 11 | H38: One detection per case regardless of rule count
A39: Partial (raised, not consistently confirmed) | C39: =COUNTIFS($B$5:$B$19,"Vulnerable",C$5:C$19,"PARTIAL") -> 0 | D39: =COUNTIFS($B$5:$B$19,"Vulnerable",D$5:D$19,"PARTIAL") -> 0 | E39: =COUNTIFS($B$5:$B$19,"Vulnerable",E$5:E$19,"PARTIAL") -> 0 | F39: =COUNTIFS($B$5:$B$19,"Vulnerable",F$5:F$19,"PARTIAL") -> 1 | H39: AI TC08
A40: Missed (FN) | C40: =COUNTIFS($B$5:$B$19,"Vulnerable",C$5:C$19,"FN") -> 7 | D40: =COUNTIFS($B$5:$B$19,"Vulnerable",D$5:D$19,"FN") -> 8 | E40: =COUNTIFS($B$5:$B$19,"Vulnerable",E$5:E$19,"FN") -> 4 | F40: =COUNTIFS($B$5:$B$19,"Vulnerable",F$5:F$19,"FN") -> 0
A41: Detection rate, strict (TP ÷ vulnerable) | C41: =IFERROR(C38/C37,0) -> 0.41666667 | D41: =IFERROR(D38/D37,0) -> 0.33333333 | E41: =IFERROR(E38/E37,0) -> 0.66666667 | F41: =IFERROR(F38/F37,0) -> 0.91666667 | H41: PARTIAL counted as miss
A42: Detection rate, lenient ((TP + PARTIAL) ÷ vulnerable) | C42: =IFERROR((C38+C39)/C37,0) -> 0.41666667 | D42: =IFERROR((D38+D39)/D37,0) -> 0.33333333 | E42: =IFERROR((E38+E39)/E37,0) -> 0.66666667 | F42: =IFERROR((F38+F39)/F37,0) -> 1 | H42: PARTIAL counted as hit
A43: Non-vulnerable cases (secure + legitimate) | C43: =COUNTIF($B$5:$B$19,"<>Vulnerable") -> 3 | D43: =COUNTIF($B$5:$B$19,"<>Vulnerable") -> 3 | E43: =COUNTIF($B$5:$B$19,"<>Vulnerable") -> 3 | F43: =COUNTIF($B$5:$B$19,"<>Vulnerable") -> 3 | H43: TC01, TC12 (+TC14)
A44: Clean on non-vulnerable (TN) | C44: =COUNTIFS($B$5:$B$19,"<>Vulnerable",C$5:C$19,"TN") -> 3 | D44: =COUNTIFS($B$5:$B$19,"<>Vulnerable",D$5:D$19,"TN") -> 2 | E44: =COUNTIFS($B$5:$B$19,"<>Vulnerable",E$5:E$19,"TN") -> 2 | F44: =COUNTIFS($B$5:$B$19,"<>Vulnerable",F$5:F$19,"TN") -> 2
A45: Flagged non-vulnerable (FP or CONTEXT) | C45: =COUNTIFS($B$5:$B$19,"<>Vulnerable",C$5:C$19,"FP")+COUNTIFS($B$5:$B$19,"<>Vulnerable",C$5:C$19,"CONTEXT") -> 0 | D45: =COUNTIFS($B$5:$B$19,"<>Vulnerable",D$5:D$19,"FP")+COUNTIFS($B$5:$B$19,"<>Vulnerable",D$5:D$19,"CONTEXT") -> 1 | E45: =COUNTIFS($B$5:$B$19,"<>Vulnerable",E$5:E$19,"FP")+COUNTIFS($B$5:$B$19,"<>Vulnerable",E$5:E$19,"CONTEXT") -> 1 | F45: =COUNTIFS($B$5:$B$19,"<>Vulnerable",F$5:F$19,"FP")+COUNTIFS($B$5:$B$19,"<>Vulnerable",F$5:F$19,"CONTEXT") -> 1 | H45: TC12 counted here for tfsec and AI
...

Sheet Evidence Register
A1: Evidence register — every factual claim the dissertation will make, traced to its evidence
A2: Status: Verified = checked against primary evidence; Provisional = depends on TC13–TC15 artefacts or AB's inter-rater check; Pending AB = needs an action from AB. Write-up rule: a claim may appear in the dissertation only if it is here, and Provisional/Pending claims must be re-checked first.
A4: ID | B4: Chapter | C4: Claim | D4: Evidence type | E4: Location | F4: Status | G4: Caveat for the write-up
A5: E01 | B5: Ch3 | C5: The study compares three conditions: A scanners only, B AI only, C hybrid. | D5: Planning document | E5: Project doc 08 Master Plan §3 | F5: Verified | G5: Executed as: scanners + AI INDEPENDENT (A and B in one job) and earlier Condition C runs.
A6: E02 | B6: Ch3 | C6: From 9 Oct 2026 12:47 the workflow default (Condition C) injected normalised scanner findings into the AI prompt via build_scanner_context(). | D6: Repository history | E6: ai-pr-review commit 732083d | F6: Verified | G6: All hybrid results TC01–TC12 come from this period.
A7: E03 | B7: Ch3 | C7: PR #69 (merged 13 Oct 09:59, merge commit 3a79020) made the workflow INDEPENDENT; metadata records scanner_findings_supplied_to_ai = false. | D7: Repository + run metadata | E7: PR #69; branch prom06-evidence: evidence/prom06/independent-runs/<run_id>/experiment-metadata.json | F7: Verified
A8: E04 | B8: Ch3 | C8: Every independent run (46) executed with INDEPENDENT condition and no scanner input to the AI. | D8: Run metadata | E8: branch prom06-evidence: evidence/prom06/independent-runs/ (46 runs, TC13–TC15 artefacts supplied by AB 13 Oct 15:50) | F8: Verified | G8: Metadata lacks the model name (hard-coded in runner).
A9: E05 | B9: Ch3 | C9: Tool configuration: Checkov 3.3.1 (--framework terraform, secrets framework not run), tfsec 1.28.14, AI claude-sonnet-4-6 via API, max_tokens 3000, no temperature set, at most 3 findings, classification policy 2.2. | D9: Code | E9: .github/workflows/terraform.yml; ai/review_runner.py; metadata | F9: Verified | G9: Model name is hard-coded, not recorded in run metadata.
A10: E06 | B10: Ch3 | C10: The AI receives the changed .tf files plus every terraform/*.tf file, ai/prompt.txt, ai/policy.md and README.md. | D10: Code | E10: ai/review_runner.py get_terraform_review_context() (lines 28–64) | F10: Verified
A11: E07 | B11: Ch3 | C11: Only CONFIRMED AI findings appear in the PR comment and the operational score. | D11: Code | E11: ai/review_runner.py format_comment(), calculate_operational_score(); ai/scoring.json | F11: Verified
A12: E08 | B12: Ch3 | C12: Ground truth for TC01–TC12 was documented before tool execution; TC13–TC15 ground truth was committed before their fixtures. | D12: Planning doc + git order | E12: Ground-Truth Matrix / Confluence v72; commit cbda52c precedes 1e87e00, 5a48d73, 049f9c9 | F12: Verified | G12: TC01–TC12 wording revised in Confluence (v72); use v72.
A13: E09 | B13: Ch3 | C13: Independent fixtures TC02–TC12 are byte-identical to the original test-case Terraform; TC01 differs by one comment. | D13: git diff | E13: branches indep-tc01…12 vs original TC commits | F13: Verified
A14: E10 | B14: Ch3 | C14: Each case ran three times on the same commit (TC08 four times, PR run failed). | D14: Run list | E14: branch prom06-evidence: evidence/prom06/independent-runs.tsv; step3/tc13-15-runs.tsv | F14: Verified
A15: E11 | B15: Ch4 | C15: Scanner output was identical across runs and matched a local reproduction with the same versions. | D15: Raw JSON | E15: branch prom06-evidence: evidence/prom06/local-scans/TC01–TC15; independent-runs/*/checkov-results.json, tfsec-results.json | F15: Verified
A16: E12 | B16: Ch4 | C16: Detection (TC01–TC12, 10 vulnerable): Checkov 5, tfsec 4, scanner union 8, AI independent 9 + 1 partial. | D16: Workbook | E16: Metrics block A; Verified Matrix | F16: Verified | G16: Descriptive only; constructed cases.
A17: E13 | B17: Ch4 | C17: Detection (TC01–TC15, 12 vulnerable): Checkov 5, tfsec 4, union 8, AI 11 + 1 partial; AI alone found TC09, TC13, TC15; no scanner-only detection. | D17: Workbook | E17: Metrics blocks B–C | F17: Verified | G17: Descriptive only; constructed cases.
A18: E14 | B18: Ch4 | C18: Checkov did not flag SSH/RDP/HTTP open to 0.0.0.0/0 (TC02–TC04) but CKV_AZURE_10 fails when the source is '*'. | D18: Local probe | E18: branch prom06-evidence: evidence/prom06/step3/probe-tc02-star/ | F18: Verified | G18: Rule value-matching blind spot, not a configuration error.
A19: E15 | B19: Ch4 | C19: TC08: the AI raised the missing NSG diagnostic setting in all four runs but classified it FALSE_POSITIVE (run failed validation), NEEDS_CONTEXT twice and CONFIRMED once. | D19: AI output | E19: branch prom06-evidence: evidence/prom06/independent-runs/38404605125 (ai_raw_response.txt), 38405066857, 38405174844, 38405218950 | F19: Verified | G19: Classification instability, not a detection miss.
A20: E16 | B20: Ch4 | C20: TC12 (legitimate HTTPS) varied across identical runs: blocked (50), LOW tag finding (95), clean (100). | D20: AI output | E20: branch prom06-evidence: evidence/prom06/independent-runs/38404619147, 38405103514, 38405210047 | F20: Verified
A21: E17 | B21: Ch4 | C21: AI run level: target confirmed in 34/37 vulnerable-case runs; false alarm in 3/9 non-vulnerable runs; one gate block. | D21: Workbook | E21: Metrics block D; AI Run Outcomes | F21: Verified
A22: E18 | B22: Ch4 | C22: 45 confirmed AI findings: 34 target, 3 extra-valid, 1 duplicate, 7 false → 82% precision. | D22: Workbook | E22: AI Confirmed Findings (labels by research assistant) | F22: Verified | G22: Labels are the assistant's judgement against ground truth; AB to spot-check the 7 FALSE labels.
A23: E19 | B23: Ch4 | C23: The AI claimed TAG-001 applies to azurerm_role_definition and azurerm_network_security_rule; applying its tag fix failed terraform validate. | D23: AI output + CI run | E23: TC10 runs 1, 3; TC12 runs 1, 2; PR #94 run 38412955313; branch prom06-evidence: evidence/prom06/step3/rem-logs/38412955313-terraform-validate.txt | F23: Verified | G23: Validate error: Unsupported argument — An argument named "tags" is not expected here (tc10_iam.tf line 14).
A24: E20 | B24: Ch4 | C24: AI quality (37 vulnerable-case runs): mean 0–2 scores — see AI Quality Scoring summary (revised 13 Oct); 46 runs scored in total. | D24: Workbook | E24: AI Quality Scoring; Scoring Rules | F24: Verified | G24: Single rubric application by AI assistant; no independent second rater (limitation).
A25: E21 | B25: Ch4 | C25: 9 of 46 runs mapped findings to an inapplicable policy, mostly SEC-001; ai/policy.md has no encryption, IAM or secrets policy. | D25: Workbook + code | E25: AI Quality Scoring col P; ai/policy.md | F25: Verified | G25: Input asymmetry: policy.md is given to the AI only.
A26: E22 | B26: Ch4 | C26: Median timing: job 77 s, AI step 31.5 s, Checkov 6 s (+19.5 s install), tfsec 1 s, PR opened → comments 79 s. | D26: GitHub jobs API | E26: branch prom06-evidence: evidence/prom06/step3/jobs/; Timing sheet | F26: Verified | G26: 1-second resolution; sequential steps.
A27: E23 | B27: Ch4 | C27: Applying each AI fix resolved the target in 12/12 cases and passed fmt/validate; 8 confirmed by the scanner that had flagged the issue. | D27: CI runs + local scans | E27: PRs #85–#97; branch prom06-evidence: evidence/prom06/step3/rem-*; Remediation Validation | F27: Verified | G27: Fixes implemented by the research assistant; one run each.
A28: E24 | B28: Ch4 | C28: With stale 'Deliberately unrestricted' comments, the AI rejected its own TC02/TC03 fixes (HIGH); with only the comment corrected it accepted them. | D28: CI runs | E28: PR #85 vs #98; #86 vs #99 | F28: Verified | G28: Single run per variant.
A29: E25 | B29: Ch4 | C29: The AI quotes in-code 'Ground truth:' comments (TC12 run 3); TC11 fixture contains a similar comment. | D29: AI output + fixture | E29: 38405210047 ai_output.json F-002; indep-tc11 tc11_requirements.tf | F29: Verified | G29: Cueing threat; links to prompt-injection literature.
A30: E26 | B30: Ch4 | C30: A PR that only deletes .tf files is not reviewed by the AI. | D30: Code + CI run | E30: review_runner.py (is_file filter); PR #93 AI comment | F30: Verified | G30: Deletion-only changes bypass AI review.
A31: E27 | B31: Ch4 | C31: Hybrid (Condition C) AI detected 10/10 vulnerable cases while citing scanner rule IDs; TC01 hybrid result is unverified. | D31: PR comments | E31: Hybrid Runs (Condition C); PRs #46, #55–#68 | F31: Verified | G31: Not comparable with independent results: scanner-informed.
A32: E28 | B32: Ch4 | C32: Hybrid severities were higher than independent (SSH/RDP CRITICAL vs HIGH); TC10 hybrid gave 2×CRITICAL then 1×HIGH on the same commit. | D32: PR comments | E32: PRs #56, #57, #66 vs #71, #72, #79 | F32: Verified
A33: E29 | B33: Ch5 | C33: The TC01 baseline and prompt were changed after early AI findings (PR #46 → #47–#54). | D33: Repository history | E33: PRs #46–#55 | F33: Verified | G33: Circularity threat.
A34: E30 | B34: Ch5 | C34: TC07 is not single-variable: Checkov fails 10 unrelated storage checks. | D34: Raw JSON | E34: branch prom06-evidence: evidence/prom06/local-scans/TC07/checkov.json | F34: Verified
A35: E31 | B35: Ch5 | C35: TC11 construct not isolated: CKV_AZURE_39 fires on the wildcard alone. | D35: Raw JSON | E35: branch prom06-evidence: evidence/prom06/local-scans/TC11 | F35: Verified
A36: E32 | B36: Ch5 | C36: The AI quality scorer was an AI assistant that had read the outputs before writing operational rules. | D36: Process record | E36: Scoring Rules sheet | F36: Verified | G36: Disclose; no inter-rater check performed (AB decision, 13 Oct).
A37: E33 | B37: Ch5 | C37: The Confluence evidence page calls the Condition C AI results 'independent' and labels TC11 as Condition B. | D37: Confluence | E37: Page 131215 v72 | F37: Verified | G37: Page left unchanged at AB's decision; explain in Ch5 if relevant.
A38: E34 | B38: Ch5 | C38: Submission deadline 26 Oct 2026 23:59. | D38: Canvas export | E38: Project doc 11 | F38: Verified | G38: From Canvas export; AB chose not to re-check live Canvas (13 Oct).
A39: E36 | B39: Ch4 | C39: Explanations overstated technical facts in some runs: Contributor described as able to change role assignments (TC13 runs 2–3, contradicted by Microsoft's role definition); an unreferenced local said to be present in state now (TC09 run 2). | D39: AI output + vendor docs | E39: branch prom06-evidence: evidence/prom06/independent-runs/38409804722, 38409830032, 38405075984; Microsoft Learn Azure built-in roles (Contributor NotActions) | F39: Verified | G39: Conditional state-exposure claims (TC09 runs 1, 3; TC15 run 2) are consistent with HashiCorp guidance and were not penalised.
A40: E37 | B40: Ch4 | C40: With its secrets framework enabled, Checkov flags the TC09 string as high-entropy (CKV_SECRET_6) but not the readable password in TC15. | D40: Local probe | E40: branch prom06-evidence: evidence/prom06/step3/probe-secrets/ | F40: Verified | G40: Probe outside the experimental configuration (pipeline runs --framework terraform only).
A41: E35 | B41: Ch3 | C41: No test PR was merged and the experimental workflow contains no terraform apply step. | D41: GitHub PR state + workflow | E41: Test PRs #56–#68 and #70–#100 unmerged (PR #69, the workflow change, was merged); .github/workflows/terraform.yml | F41: Verified | G41: A Terraform Cloud check also ran on PRs (speculative plan, to confirm); close PRs unmerged after sign-off.

Sheet Figures & Tables
A1: Planned figures, screenshots, tables and appendices (provisional numbering)
A2: Figures F* are rendered at 300 dpi from this workbook by scripts in the evidence branch. Screenshots S* must be captured by AB from GitHub (the assistant cannot screenshot web pages). Excluded from the word count per the brief.
A4: Kind | B4: No. | C4: Chapter | D4: Content | E4: Source | F4: Status | G4: Note
A5: Figure | B5: F3.1 | C5: Ch3 | D5: Experimental pipeline and conditions | E5: figures/fig_architecture.png (Graphviz source .dot) | F5: Ready | G5: Shows Condition C injection path.
A6: Figure | B6: F4.1 | C6: Ch4 | D6: Detection outcome by case and tool (TC01–TC15) | E6: figures/fig_detection_matrix.png | F6: Ready
A7: Figure | B7: F4.2 | C7: Ch4 | D7: Detection rate by tool, two case sets | E7: figures/fig_detection_rates.png | F7: Ready
A8: Figure | B8: F4.3 | C8: Ch4 | D8: AI explanation/remediation quality by rubric dimension | E8: figures/fig_ai_quality.png | F8: Ready
A9: Figure | B9: F4.4 | C9: Ch4 | D9: Median pipeline timings | E9: figures/fig_timing.png | F9: Ready
A10: Figure | B10: F4.5 | C10: Ch4 | D10: Remediation validation outcomes | E10: figures/fig_remediation.png | F10: Ready
A11: Screenshot | B11: S1 | C11: Ch4 | D11: PR #71 (TC02): Checkov clean vs tfsec and AI findings | E11: GitHub PR page | F11: Pending AB
A12: Screenshot | B12: S2 | C12: Ch4 | D12: PR #78 (TC09): AI-only detection of an embedded secret | E12: GitHub PR page | F12: Pending AB
A13: Screenshot | B13: S3 | C13: Ch4 | D13: PR #77 (TC08): failed run / validation rejection | E13: GitHub Actions run 38404605125 | F13: Pending AB
A14: Screenshot | B14: S4 | C14: Ch4 | D14: PR #81 (TC12): block on legitimate HTTPS (run 1) | E14: GitHub PR page | F14: Pending AB
A15: Screenshot | B15: S5 | C15: Ch4 | D15: PRs #82 and #84 (TC13, TC15): AI-only detections | E15: GitHub PR pages | F15: Pending AB
A16: Screenshot | B16: S6 | C16: Ch4 | D16: PR #85 vs #98: stale comment changes the AI verdict | E16: GitHub PR pages | F16: Pending AB
A17: Screenshot | B17: S7 | C17: Ch4 | D17: PR #94: AI tag fix fails terraform validate | E17: GitHub Actions run 38412955313 (log text already archived) | F17: Pending AB | G17: Optional: log text can be shown as a code listing instead.
A18: Screenshot | B18: S8 | C18: Ch3 | D18: Run summary page showing uploaded artefacts | E18: Any independent run | F18: Pending AB
A19: Table | B19: T3.1 | C19: Ch3 | D19: Test cases TC01–TC15 with ground truth and purpose | E19: Confluence v72; ground-truth/TC13-TC15 | F19: To produce
A20: Table | B20: T3.2 | C20: Ch3 | D20: Tool versions and configuration | E20: E05, E06 | F20: To produce
A21: Table | B21: T3.3 | C21: Ch3 | D21: Classification codes and normalisation rules | E21: Verified Matrix README; Decisions & Caveats | F21: To produce
A22: Table | B22: T3.4 | C22: Ch3 | D22: Remediation-quality rubric with operational rules | E22: Scoring Rules | F22: To produce
A23: Table | B23: T4.1 | C23: Ch4 | D23: Case-level detection metrics | E23: Metrics A–C | F23: To produce
A24: Table | B24: T4.2 | C24: Ch4 | D24: AI run-level metrics and confirmed-finding precision | E24: Metrics D | F24: To produce
A25: Table | B25: T4.3 | C25: Ch4 | D25: False confirmed AI findings (7) with explanation | E25: AI Confirmed Findings | F25: To produce
A26: Table | B26: T4.4 | C26: Ch4 | D26: Remediation validation by case | E26: Remediation Validation | F26: To produce
A27: Table | B27: T4.5 | C27: Ch4 | D27: Independent vs hybrid AI (TC01–TC12) | E27: Hybrid Runs; Verified Matrix | F27: To produce
A28: Table | B28: T5.1 | C28: Ch5 | D28: Threats to validity and mitigations | E28: E29–E33, Decisions & Caveats | F28: To produce
A29: Appendix | B29: App A | C29: — | D29: Evidence index (branch, paths, run IDs, PRs) | E29: This register + evidence README | F29: To produce
... A33: Appendix | B33: App E | C33: — | D33: Project management record | E33: Project doc 07 (PROM05 plan) + actual timeline | F33: To produce

Sheet Independent AI Runs
A1: Test case | B1: PR | C1: Run ID | D1: Event | E1: Started (UTC) | F1: Commit | G1: Condition (metadata) | H1: Scanner findings supplied to AI | I1: AI output status | J1: Confirmed findings | K1: Other findings (not in PR comment) | L1: Operational score | M1: Verdict
A2: TC01 | B2: 70 | C2: 38404582550 | D2: pull_request | E2: 2026-10-13 13:23:46 | F2: 92ab884 | G2: INDEPENDENT | H2: FALSE | I2: parsed | J2: none | K2: FALSE_POSITIVE · INFORMATIONAL · Private DNS zone name extraction via split() index — plausible concern, not a defect | L2: 100 | M2: APPROVE
A3: TC01 | B3: 70 | C3: 38405003190 | D3: workflow_dispatch | E3: 2026-10-13 13:26:53 | F3: 92ab884 | G3: INDEPENDENT | H3: FALSE | I3: parsed | J3: none | K3: none | L3: 100 | M3: APPROVE
A4: TC01 | B4: 70 | C4: 38405111880 | D4: workflow_dispatch | E4: 2026-10-13 13:27:41 | F4: 92ab884 | G4: INDEPENDENT | H4: FALSE | I4: parsed | J4: none | K4: FALSE_POSITIVE · INFORMATIONAL · NSG deny-all outbound rule may be flagged as redundant by scanners FALSE_POSITIVE · INFORMATIONAL · DDoS Protection Standard not enabled — inapplicable to research workload FALSE_POSITIVE · INFORMATIONAL · Subnet NSG association is correctly configured | L4: 100 | M4: APPROVE
A5: TC02 | B5: 71 | C5: 38404584887 | D5: pull_request | E5: 2026-10-13 13:23:46 | F5: 3eda6f7 | G5: INDEPENDENT | H5: FALSE | I5: parsed | J5: HIGH · SECURITY_VULNERABILITY · Unrestricted inbound SSH access permitted from any source address | K5: none | L5: 70 | M5: APPROVE_WITH_COMMENTS
A6: TC02 | B6: 71 | C6: 38405012851 | D6: workflow_dispatch | E6: 2026-10-13 13:26:59 | F6: 3eda6f7 | G6: INDEPENDENT | H6: FALSE | I6: parsed | J6: HIGH · SECURITY_VULNERABILITY · Inbound SSH (port 22) permitted from any source address (0.0.0.0/0) | K6: none | L6: 70 | M6: APPROVE_WITH_COMMENTS
A7: TC02 | B7: 71 | C7: 38405121064 | D7: workflow_dispatch | E7: 2026-10-13 13:27:45 | F7: 3eda6f7 | G7: INDEPENDENT | H7: FALSE | I7: parsed | J7: HIGH · SECURITY_VULNERABILITY · NSG permits inbound SSH (TCP/22) from any source (0.0.0.0/0) | K7: none | L7: 70 | M7: APPROVE_WITH_COMMENTS
A8: TC03 | B8: 72 | C8: 38404589228 | D8: pull_request | E8: 2026-10-13 13:23:47 | F8: 27789d9 | G8: INDEPENDENT | H8: FALSE | I8: parsed | J8: HIGH · SECURITY_VULNERABILITY · RDP (TCP/3389) publicly accessible from any source address | K8: none | L8: 70 | M8: APPROVE_WITH_COMMENTS
A9: TC03 | B9: 72 | C9: 38405022162 | D9: workflow_dispatch | E9: 2026-10-13 13:27:00 | F9: 27789d9 | G9: INDEPENDENT | H9: FALSE | I9: parsed | J9: HIGH · SECURITY_VULNERABILITY · Unrestricted inbound RDP (port 3389) permitted from 0.0.0.0/0 | K9: none | L9: 70 | M9: APPROVE_WITH_COMMENTS
A10: TC03 | B10: 72 | C10: 38405130215 | D10: workflow_dispatch | E10: 2026-10-13 13:27:48 | F10: 27789d9 | G10: INDEPENDENT | H10: FALSE | I10: parsed | J10: HIGH · SECURITY_VULNERABILITY · Unrestricted inbound RDP access from any source (0.0.0.0/0) on port 3389 HIGH · POLICY_OR_COMPLIANCE · SEC-001 violation: public RDP exposure without documented policy justification | K10: none | L10: 40 | M10: DO_NOT_MERGE
A11: TC04 | B11: 73 | C11: 38404592498 | D11: pull_request | E11: 2026-10-13 13:23:50 | F11: cbc6855 | G11: INDEPENDENT | H11: FALSE | I11: parsed | J11: HIGH · SECURITY_VULNERABILITY · Unrestricted inbound HTTP (TCP/80) permitted from any source via NSG rule | K11: none | L11: 70 | M11: APPROVE_WITH_COMMENTS
A12: TC04 | B12: 73 | C12: 38405031009 | D12: workflow_dispatch | E12: 2026-10-13 13:27:06 | F12: cbc6855 | G12: INDEPENDENT | H12: FALSE | I12: parsed | J12: HIGH · SECURITY_VULNERABILITY · NSG allows unrestricted inbound HTTP (TCP/80) from any IPv4 address | K12: none | L12: 70 | M12: APPROVE_WITH_COMMENTS
A13: TC04 | B13: 73 | C13: 38405139458 | D13: workflow_dispatch | E13: 2026-10-13 13:27:53 | F13: cbc6855 | G13: INDEPENDENT | H13: FALSE | I13: parsed | J13: HIGH · SECURITY_VULNERABILITY · NSG rule permits unrestricted inbound HTTP (TCP/80) from any IPv4 source | K13: none | L13: 70 | M13: APPROVE_WITH_COMMENTS
... A22: TC07 | B22: 76 | C22: 38405166219 | D22: workflow_dispatch | E22: 2026-10-13 13:28:05 | F22: b6e93b7 | G22: INDEPENDENT | H22: FALSE | I22: parsed | J22: HIGH · SECURITY_VULNERABILITY · Storage account permits deprecated TLS 1.0 connections LOW · POLICY_OR_COMPLIANCE · Storage account missing mandatory tags: owner and cost-center | K22: NEEDS_CONTEXT · HIGH · Storage account may be publicly accessible with no network restriction | L22: 65 | M22: DO_NOT_MERGE
A23: TC08 | B23: 77 | C23: 38404605125 | D23: pull_request | E23: 2026-10-13 13:23:55 | F23: c86e4d5 | G23: INDEPENDENT | H23: FALSE | I23: AI step failed | J23: — | K23: Output rejected by validator: FALSE_POSITIVE/INFORMATIONAL 'No azurerm_monitor_diagnostic_setting configured for the NSG' with a policy mapping to a non-confirmed finding | L23: — | M23: —
A24: TC08 | B24: 77 | C24: 38405066857 | D24: workflow_dispatch | E24: 2026-10-13 13:27:23 | F24: c86e4d5 | G24: INDEPENDENT | H24: FALSE | I24: parsed | J24: none | K24: NEEDS_CONTEXT · MEDIUM · No diagnostic setting configured for the NSG resource FALSE_POSITIVE · INFORMATIONAL · Explicit outbound deny rule is intentional defense-in-depth, not redundant FALSE_POSITIVE · INFORMATIONAL · Private-only Log Analytics access is intentional; no client workload in TC01 scope | L24: 100 | M24: APPROVE
A25: TC08 | B25: 77 | C25: 38405174844 | D25: workflow_dispatch | E25: 2026-10-13 13:28:07 | F25: c86e4d5 | G25: INDEPENDENT | H25: FALSE | I25: parsed | J25: none | K25: NEEDS_CONTEXT · MEDIUM · No azurerm_monitor_diagnostic_setting configured for the NSG resource | L25: 100 | M25: APPROVE
A26: TC08 | B26: 77 | C26: 38405218950 | D26: workflow_dispatch | E26: 2026-10-13 13:28:40 | F26: c86e4d5 | G26: INDEPENDENT | H26: FALSE | I26: parsed | J26: MEDIUM · POLICY_OR_COMPLIANCE · No diagnostic setting configured to forward NSG logs to Log Analytics | K26: none | L26: 85 | M26: APPROVE
A27: TC09 | B27: 78 | C27: 38404607277 | D27: pull_request | E27: 2026-10-13 13:23:54 | F27: 277a730 | G27: INDEPENDENT | H27: FALSE | I27: parsed | J27: MEDIUM · SECURITY_VULNERABILITY · Hardcoded secret value embedded in Terraform local in source-controlled file | K27: none | L27: 85 | M27: APPROVE
A28: TC09 | B28: 78 | C28: 38405075984 | D28: workflow_dispatch | E28: 2026-10-13 13:27:28 | F28: 277a730 | G28: INDEPENDENT | H28: FALSE | I28: parsed | J28: MEDIUM · SECURITY_VULNERABILITY · Hardcoded credential-shaped string stored as a plaintext Terraform local in source control | K28: none | L28: 85 | M28: APPROVE
A29: TC09 | B29: 78 | C29: 38405183161 | D29: workflow_dispatch | E29: 2026-10-13 13:28:12 | F29: 277a730 | G29: INDEPENDENT | H29: FALSE | I29: parsed | J29: MEDIUM · SECURITY_VULNERABILITY · Hardcoded secret-like string embedded in Terraform local value | K29: none | L29: 85 | M29: APPROVE
A30: TC10 | B30: 79 | C30: 38404612132 | D30: pull_request | E30: 2026-10-13 13:23:59 | F30: bd8a61f | G30: INDEPENDENT | H30: FALSE | I30: parsed | J30: HIGH · SECURITY_VULNERABILITY · Custom role definition grants unrestricted wildcard ('*') permissions at subscription scope LOW · POLICY_OR_COMPLIANCE · Custom role definition is missing mandatory tags required by TAG-001 | K30: none | L30: 65 | M30: DO_NOT_MERGE
A31: TC10 | B31: 79 | C31: 38405084901 | D31: workflow_dispatch | E31: 2026-10-13 13:27:31 | F31: bd8a61f | G31: INDEPENDENT | H31: FALSE | I31: parsed | J31: HIGH · SECURITY_VULNERABILITY · Custom role definition grants wildcard (*) permissions at subscription scope | K31: none | L31: 70 | M31: APPROVE_WITH_COMMENTS
A32: TC10 | B32: 79 | C32: 38405192342 | D32: workflow_dispatch | E32: 2026-10-13 13:28:16 | F32: bd8a61f | G32: INDEPENDENT | H32: FALSE | I32: parsed | J32: HIGH · SECURITY_VULNERABILITY · Subscription-scoped wildcard role definition grants unrestricted ARM permissions LOW · POLICY_OR_COMPLIANCE · Custom role definition missing mandatory tags required by TAG-001 | K32: none | L32: 65 | M32: DO_NOT_MERGE
A33: TC11 | B33: 80 | C33: 38404613836 | D33: pull_request | E33: 2026-10-13 13:23:57 | F33: 3dd9a04 | G33: INDEPENDENT | H33: FALSE | I33: parsed | J33: HIGH · SECURITY_VULNERABILITY · Custom RBAC role grants wildcard (*) permissions at subscription scope, violating least privilege | K33: none | L33: 70 | M33: APPROVE_WITH_COMMENTS
A34: TC11 | B34: 80 | C34: 38405093864 | D34: workflow_dispatch | E34: 2026-10-13 13:27:32 | F34: 3dd9a04 | G34: INDEPENDENT | H34: FALSE | I34: parsed | J34: HIGH · SECURITY_VULNERABILITY · Custom role grants wildcard subscription-scope permissions far exceeding documented task requirements | K34: none | L34: 70 | M34: APPROVE_WITH_COMMENTS
A35: TC11 | B35: 80 | C35: 38405200842 | D35: workflow_dispatch | E35: 2026-10-13 13:28:23 | F35: 3dd9a04 | G35: INDEPENDENT | H35: FALSE | I35: parsed | J35: HIGH · SECURITY_VULNERABILITY · Custom role definition grants wildcard subscription-scope permissions far exceeding documented task requirements | K35: none | L35: 70 | M35: APPROVE_WITH_COMMENTS
... A38: TC12 | B38: 81 | C38: 38405210047 | D38: workflow_dispatch | E38: 2026-10-13 13:28:25 | F38: 9cee1fe | G38: INDEPENDENT | H38: FALSE | I38: parsed | J38: none | K38: NEEDS_CONTEXT · MEDIUM · AllowPublicHTTPS-TC12 rule uses wildcard destination address prefix FALSE_POSITIVE · INFORMATIONAL · Public inbound HTTPS rule is explicitly justified — not a SEC-001 violation FALSE_POSITIVE · INFORMATIONAL · azurerm_network_security_rule does not support tags — TAG-001 not applicable | L38: 100 | M38: APPROVE
A40: Source: experiment-metadata.json and ai_output.json in each prom06-INDEPENDENT-<run_id> artifact (downloaded by AB, 13 Oct 2026). Model: claude-sonnet-4-6 (hard-coded in ai/review_runner.py; not recorded in metadata); no temperature set.

Sheet AI Run Outcomes
A1: AI independent condition — one row per run (46 runs)
A2: Counts (black) are formulas over 'AI Confirmed Findings'. Score/decision: TC01–TC12 linked from 'Independent AI Runs' (green); TC13–TC15 typed from ai_output.json operational_score and verdict in the run artefacts (blue).
A4: TC | B4: Run | C4: Run ID | D4: Case type | E4: Confirmed findings | F4: TARGET | G4: EXTRA-VALID | H4: DUPLICATE | I4: FALSE | J4: Target confirmed? | K4: Operational score | L4: Decision
A5: TC01 | B5: 1 | C5: 38404582550 | D5: Secure | E5: =COUNTIFS('AI Confirmed Findings'!$C$6:$C$59,C5,'AI Confirmed Findings'!$G$6:$G$59,"<>NONE") -> 0 | F5: =COUNTIFS('AI Confirmed Findings'!$C$6:$C$59,C5,'AI Confirmed Findings'!$G$6:$G$59,"TARGET") -> 0 | G5: =COUNTIFS('AI Confirmed Findings'!$C$6:$C$59,C5,'AI Confirmed Findings'!$G$6:$G$59,"EXTRA-VALID") -> 0 | H5: =COUNTIFS('AI Confirmed Findings'!$C$6:$C$59,C5,'AI Confirmed Findings'!$G$6:$G$59,"DUPLICATE") -> 0 | I5: =COUNTIFS('AI Confirmed Findings'!$C$6:$C$59,C5,'AI Confirmed Findings'!$G$6:$G$59,"FALSE") -> 0 | J5: =IF(D5="Vulnerable",IF(F5>0,"Y","N"),"n/a") -> n/a | K5: ='Independent AI Runs'!L2 -> 100 | L5: ='Independent AI Runs'!M2 -> APPROVE
A6: TC01 | B6: 2 | C6: 38405003190 | D6: Secure | E6: =COUNTIFS('AI Confirmed Findings'!$C$6:$C$59,C6,'AI Confirmed Findings'!$G$6:$G$59,"<>NONE") -> 0 | F6: =COUNTIFS('AI Confirmed Findings'!$C$6:$C$59,C6,'AI Confirmed Findings'!$G$6:$G$59,"TARGET") -> 0 | G6: =COUNTIFS('AI Confirmed Findings'!$C$6:$C$59,C6,'AI Confirmed Findings'!$G$6:$G$59,"EXTRA-VALID") -> 0 | H6: =COUNTIFS('AI Confirmed Findings'!$C$6:$C$59,C6,'AI Confirmed Findings'!$G$6:$G$59,"DUPLICATE") -> 0 | I6: =COUNTIFS('AI Confirmed Findings'!$C$6:$C$59,C6,'AI Confirmed Findings'!$G$6:$G$59,"FALSE") -> 0 | J6: =IF(D6="Vulnerable",IF(F6>0,"Y","N"),"n/a") -> n/a | K6: ='Independent AI Runs'!L3 -> 100 | L6: ='Independent AI Runs'!M3 -> APPROVE
A7: TC01 | B7: 3 | C7: 38405111880 | D7: Secure | E7: =COUNTIFS('AI Confirmed Findings'!$C$6:$C$59,C7,'AI Confirmed Findings'!$G$6:$G$59,"<>NONE") -> 0 | F7: =COUNTIFS('AI Confirmed Findings'!$C$6:$C$59,C7,'AI Confirmed Findings'!$G$6:$G$59,"TARGET") -> 0 | G7: =COUNTIFS('AI Confirmed Findings'!$C$6:$C$59,C7,'AI Confirmed Findings'!$G$6:$G$59,"EXTRA-VALID") -> 0 | H7: =COUNTIFS('AI Confirmed Findings'!$C$6:$C$59,C7,'AI Confirmed Findings'!$G$6:$G$59,"DUPLICATE") -> 0 | I7: =COUNTIFS('AI Confirmed Findings'!$C$6:$C$59,C7,'AI Confirmed Findings'!$G$6:$G$59,"FALSE") -> 0 | J7: =IF(D7="Vulnerable",IF(F7>0,"Y","N"),"n/a") -> n/a | K7: ='Independent AI Runs'!L4 -> 100 | L7: ='Independent AI Runs'!M4 -> APPROVE
A8: TC02 | B8: 1 | C8: 38404584887 | D8: Vulnerable | E8: =COUNTIFS('AI Confirmed Findings'!$C$6:$C$59,C8,'AI Confirmed Findings'!$G$6:$G$59,"<>NONE") -> 1 | F8: =COUNTIFS('AI Confirmed Findings'!$C$6:$C$59,C8,'AI Confirmed Findings'!$G$6:$G$59,"TARGET") -> 1 | G8: =COUNTIFS('AI Confirmed Findings'!$C$6:$C$59,C8,'AI Confirmed Findings'!$G$6:$G$59,"EXTRA-VALID") -> 0 | H8: =COUNTIFS('AI Confirmed Findings'!$C$6:$C$59,C8,'AI Confirmed Findings'!$G$6:$G$59,"DUPLICATE") -> 0 | I8: =COUNTIFS('AI Confirmed Findings'!$C$6:$C$59,C8,'AI Confirmed Findings'!$G$6:$G$59,"FALSE") -> 0 | J8: =IF(D8="Vulnerable",IF(F8>0,"Y","N"),"n/a") -> Y | K8: ='Independent AI Runs'!L5 -> 70 | L8: ='Independent AI Runs'!M5 -> APPROVE_WITH_COMMENTS
A9: TC02 | B9: 2 | C9: 38405012851 | D9: Vulnerable | E9: =COUNTIFS('AI Confirmed Findings'!$C$6:$C$59,C9,'AI Confirmed Findings'!$G$6:$G$59,"<>NONE") -> 1 | F9: =COUNTIFS('AI Confirmed Findings'!$C$6:$C$59,C9,'AI Confirmed Findings'!$G$6:$G$59,"TARGET") -> 1 | G9: =COUNTIFS('AI Confirmed Findings'!$C$6:$C$59,C9,'AI Confirmed Findings'!$G$6:$G$59,"EXTRA-VALID") -> 0 | H9: =COUNTIFS('AI Confirmed Findings'!$C$6:$C$59,C9,'AI Confirmed Findings'!$G$6:$G$59,"DUPLICATE") -> 0 | I9: =COUNTIFS('AI Confirmed Findings'!$C$6:$C$59,C9,'AI Confirmed Findings'!$G$6:$G$59,"FALSE") -> 0 | J9: =IF(D9="Vulnerable",IF(F9>0,"Y","N"),"n/a") -> Y | K9: ='Independent AI Runs'!L6 -> 70 | L9: ='Independent AI Runs'!M6 -> APPROVE_WITH_COMMENTS
A10: TC02 | B10: 3 | C10: 38405121064 | D10: Vulnerable | E10: =COUNTIFS('AI Confirmed Findings'!$C$6:$C$59,C10,'AI Confirmed Findings'!$G$6:$G$59,"<>NONE") -> 1 | F10: =COUNTIFS('AI Confirmed Findings'!$C$6:$C$59,C10,'AI Confirmed Findings'!$G$6:$G$59,"TARGET") -> 1 | G10: =COUNTIFS('AI Confirmed Findings'!$C$6:$C$59,C10,'AI Confirmed Findings'!$G$6:$G$59,"EXTRA-VALID") -> 0 | H10: =COUNTIFS('AI Confirmed Findings'!$C$6:$C$59,C10,'AI Confirmed Findings'!$G$6:$G$59,"DUPLICATE") -> 0 | I10: =COUNTIFS('AI Confirmed Findings'!$C$6:$C$59,C10,'AI Confirmed Findings'!$G$6:$G$59,"FALSE") -> 0 | J10: =IF(D10="Vulnerable",IF(F10>0,"Y","N"),"n/a") -> Y | K10: ='Independent AI Runs'!L7 -> 70 | L10: ='Independent AI Runs'!M7 -> APPROVE_WITH_COMMENTS
A11: TC03 | B11: 1 | C11: 38404589228 | D11: Vulnerable | E11: =COUNTIFS('AI Confirmed Findings'!$C$6:$C$59,C11,'AI Confirmed Findings'!$G$6:$G$59,"<>NONE") -> 1 | F11: =COUNTIFS('AI Confirmed Findings'!$C$6:$C$59,C11,'AI Confirmed Findings'!$G$6:$G$59,"TARGET") -> 1 | G11: =COUNTIFS('AI Confirmed Findings'!$C$6:$C$59,C11,'AI Confirmed Findings'!$G$6:$G$59,"EXTRA-VALID") -> 0 | H11: =COUNTIFS('AI Confirmed Findings'!$C$6:$C$59,C11,'AI Confirmed Findings'!$G$6:$G$59,"DUPLICATE") -> 0 | I11: =COUNTIFS('AI Confirmed Findings'!$C$6:$C$59,C11,'AI Confirmed Findings'!$G$6:$G$59,"FALSE") -> 0 | J11: =IF(D11="Vulnerable",IF(F11>0,"Y","N"),"n/a") -> Y | K11: ='Independent AI Runs'!L8 -> 70 | L11: ='Independent AI Runs'!M8 -> APPROVE_WITH_COMMENTS
A12: TC03 | B12: 2 | C12: 38405022162 | D12: Vulnerable | E12: =COUNTIFS('AI Confirmed Findings'!$C$6:$C$59,C12,'AI Confirmed Findings'!$G$6:$G$59,"<>NONE") -> 1 | F12: =COUNTIFS('AI Confirmed Findings'!$C$6:$C$59,C12,'AI Confirmed Findings'!$G$6:$G$59,"TARGET") -> 1 | G12: =COUNTIFS('AI Confirmed Findings'!$C$6:$C$59,C12,'AI Confirmed Findings'!$G$6:$G$59,"EXTRA-VALID") -> 0 | H12: =COUNTIFS('AI Confirmed Findings'!$C$6:$C$59,C12,'AI Confirmed Findings'!$G$6:$G$59,"DUPLICATE") -> 0 | I12: =COUNTIFS('AI Confirmed Findings'!$C$6:$C$59,C12,'AI Confirmed Findings'!$G$6:$G$59,"FALSE") -> 0 | J12: =IF(D12="Vulnerable",IF(F12>0,"Y","N"),"n/a") -> Y | K12: ='Independent AI Runs'!L9 -> 70 | L12: ='Independent AI Runs'!M9 -> APPROVE_WITH_COMMENTS
A13: TC03 | B13: 3 | C13: 38405130215 | D13: Vulnerable | E13: =COUNTIFS('AI Confirmed Findings'!$C$6:$C$59,C13,'AI Confirmed Findings'!$G$6:$G$59,"<>NONE") -> 2 | F13: =COUNTIFS('AI Confirmed Findings'!$C$6:$C$59,C13,'AI Confirmed Findings'!$G$6:$G$59,"TARGET") -> 1 | G13: =COUNTIFS('AI Confirmed Findings'!$C$6:$C$59,C13,'AI Confirmed Findings'!$G$6:$G$59,"EXTRA-VALID") -> 0 | H13: =COUNTIFS('AI Confirmed Findings'!$C$6:$C$59,C13,'AI Confirmed Findings'!$G$6:$G$59,"DUPLICATE") -> 1 | I13: =COUNTIFS('AI Confirmed Findings'!$C$6:$C$59,C13,'AI Confirmed Findings'!$G$6:$G$59,"FALSE") -> 0 | J13: =IF(D13="Vulnerable",IF(F13>0,"Y","N"),"n/a") -> Y | K13: ='Independent AI Runs'!L10 -> 40 | L13: ='Independent AI Runs'!M10 -> DO_NOT_MERGE
