Workbook

Sheet README
A1: PROM06 TC01–TC12 Verified Results Matrix
A2: Built 13 Oct 2026 from: PR bot comments and run artifacts (PRs #46–#68 Condition C; PRs #70–#81 independent), experiment-metadata.json for 37 independent runs, local reproduction with Checkov 3.3.1 and tfsec 1.28.14, Ground-Truth Matrix v1.0 and Confluence PROM06-TC-Evidences v72 (13 Oct 10:47).
A3: Evidence hierarchy used: raw run artifacts > PR bot comments > Confluence/screenshots > draft matrix.
A4: Classification codes (target condition only):
A5: TP = target condition correctly reported FN = target condition not reported TN = no finding on a case with no intended weakness
A6: FP = finding that treats an acceptable configuration as a defect PARTIAL = reported inconsistently across runs CONTEXT = context-sensitive, researcher decision needed UNVERIFIED = evidence conflict, not usable
A7: AI (independent) = post-PR #69 workflow, scanner_findings_supplied_to_ai = false in every run's metadata, 3 successful runs per case (TC08: 3 successful + 1 failed). AI (hybrid) = earlier Condition C runs whose prompt contained normalised Checkov/tfsec findings.
A8: Severity labels are each tool's own scale and are not equivalent across tools (Checkov OSS JSON has no severity).
A9: Sheets: Verified Matrix · Summary (formula-driven counts) · Independent AI Runs · Scanner Results · Hybrid Runs (Condition C) · Decisions & Caveats · Draft Matrix (original).
A10: Decisions & Caveats: all ten proposed treatments agreed by AB on 13 Oct 2026; classifications in 'Verified Matrix' reflect them. Matrix frozen pending AI explanation/remediation scoring.

Sheet Verified Matrix
A1: Test case | B1: Scenario (Confluence v72) | C1: Ground truth (summary) | D1: Case type | E1: Checkov 3.3.1 observed | F1: Checkov class. | G1: tfsec 1.28.14 observed | H1: tfsec class. | I1: AI independent (3 runs) | J1: AI indep. class. | K1: AI hybrid / Condition C (earlier) | L1: AI hybrid class. | M1: Extra / unrelated findings | N1: Evidence references | O1: Caveats
A2: TC01 | B2: Secure baseline | C2: No intentional vulnerability (false-positive baseline). | D2: Secure | E2: 7 passed / 0 failed | F2: TN | G2: 0 findings | H2: TN | I2: 0 confirmed in 3/3 runs (100/100). Only FALSE_POSITIVE/INFORMATIONAL notes in the artifact. | J2: TN | K2: Conflicting: PR #46 (older fixture) 2 confirmed MEDIUM (TAG-001, LOG-001), 55/100; Confluence 'clean' screenshot from PR #55 cannot be tied to its own run. | L2: UNVERIFIED | M2: None confirmed. | N2: PR #70, 92ab884, runs 38404582550 / 38405003190 / 38405111880; hybrid PR #46, #55 | O2: Baseline evolved after PR #46 AI findings (tags, logging, deny rules) and prompt was adjusted — disclose as validity threat. TC01 rerun branch has a comment-only edit.
A3: TC02 | B3: Unrestricted SSH Access | C3: Inbound TCP/22 from 0.0.0.0/0 — genuine management-plane exposure. | D3: Vulnerable | E3: 7/0 — CKV_AZURE_10 evaluated and PASSED | F3: FN | G3: AVD-AZU-0047 + AVD-AZU-0050 (CRITICAL) | H3: TP | I3: HIGH SSH finding in 3/3 runs (70/100). | J3: TP | K3: CRITICAL SSH, cited tfsec IDs (PR #56). | L3: TP | M3: tfsec: 2 rules for one condition (normalise to 1). | N3: PR #71, 3eda6f7; hybrid PR #56 | O3: Checkov passes because '0.0.0.0/0' is not matched as internet; CKV_AZURE_10 fails when the source is '*' (local probe).
A4: TC03 | B4: Unrestricted RDP Access | C4: Inbound TCP/3389 from 0.0.0.0/0 — genuine management-plane exposure. | D4: Vulnerable | E4: 7/0 — CKV_AZURE_9 evaluated and PASSED | F4: FN | G4: AVD-AZU-0048 + AVD-AZU-0047 (CRITICAL) | H4: TP | I4: HIGH RDP finding in 3/3 runs; run 3 added a duplicate SEC-001 policy finding (40/100). | J4: TP | K4: CRITICAL RDP, cited tfsec IDs (PR #57). | L4: TP | M4: AI run 3: duplicate SEC-001 finding for the same condition; tfsec: 2 rules, 1 condition. | N4: PR #72, 27789d9; hybrid PR #57 | O4: Same Checkov source-matching behaviour as TC02 (inferred; probe run on TC02 only).
A5: TC04 | B5: Public HTTP Ingress | C5: Inbound TCP/80 from 0.0.0.0/0 — intended TC04 weakness (Confluence v72). | D5: Vulnerable | E5: 7/0 — CKV_AZURE_160 evaluated and PASSED | F5: FN | G5: AVD-AZU-0047 (CRITICAL, generic public ingress) | H5: TP | I5: HIGH HTTP finding in 3/3 runs (70/100). | J5: TP | K5: HIGH HTTP, cited tfsec ID (PR #58). | L5: TP | M5: — | N5: PR #73, cbc6855; hybrid PR #58 | O5: GT v1.0 described TC04 as context-dependent; Confluence v72 fixes it as an intended weakness. tfsec rule is not port-specific.
A6: TC05 | B6: Missing NSG Association | C6: NSG exists but is not associated with the subnet — control not effective. | D6: Vulnerable | E6: CKV2_AZURE_31 (6 passed / 1 failed) | F6: TP | G6: 0 findings | H6: FN | I6: NET-001 finding in 3/3 runs (HIGH, HIGH, MEDIUM). | J6: TP | K6: MEDIUM NET-001, cited Checkov ID (PR #59). | L6: TP | M6: AI: NEEDS_CONTEXT note in every run about the stale 'Custom resolver' DNS comment (fixture artefact). | N6: PR #74, 14486bd; hybrid PR #59 | O6: Severity varied across identical runs.
A7: TC06 | B7: Public DNS Configuration | C7: VNet uses public resolver 8.8.8.8 contrary to NET-002 / CKV_AZURE_183. | D7: Vulnerable | E7: CKV_AZURE_183 + CKV_AZURE_182 (5/2) | F7: TP | G7: 0 findings | H7: FN | I7: MEDIUM NET-002 finding in 3/3 runs (85/100). | J7: TP | K7: MEDIUM NET-002, cited Checkov IDs (PR #61). | L7: TP | M7: Checkov CKV_AZURE_182 (≥2 DNS endpoints) is related but not the target condition. | N7: PR #75, eb51ee9; hybrid PR #61 | O7: Ground truth depends on the project baseline (NET-002); public DNS is not inherently insecure.
A8: TC07 | B8: Weak TLS Configuration | C8: Storage account min_tls_version = TLS1_0 below TLS 1.2 minimum. | D8: Vulnerable | E8: CKV_AZURE_44 among 11 failed (11/11) | F8: TP | G8: AVD-AZU-0011 (CRITICAL) | H8: TP | I8: HIGH TLS finding in 3/3 runs + LOW TAG-001 (65/100). | J8: TP | K8: CRITICAL TLS + 2 extra findings (PR #63). | L8: TP | M8: Checkov: 10 unrelated storage checks fail. AI: valid LOW TAG-001 (storage is taggable) + NEEDS_CONTEXT public access. | N8: PR #76, b6e93b7; hybrid PR #63 | O8: Fixture not single-variable (new storage account, hard-coded RG, non-standard tags); Confluence scenario said TC12 HTTPS service would be reused.
A9: TC08 | B9: Missing Diagnostic/Audit Logging | C9: NSG diagnostic setting removed; logs not forwarded to Log Analytics (LOG-001). | D9: Vulnerable | E9: 7/0 | F9: FN | G9: 0 findings | H9: FN | I9: Raised in all 4 runs but classified inconsistently: FALSE_POSITIVE (output rejected, run failed), NEEDS_CONTEXT ×2, CONFIRMED ×1. | J9: PARTIAL | K9: MEDIUM LOG-001 confirmed (PR #64). | L9: TP | M9: — | N9: PR #77, c86e4d5, runs 38404605125 (failed) / 38405066857 / 38405174844 / 38405218950; hybrid PR #64 | O9: Only the AI is given LOG-001; failed run's summary wrongly claimed the absence was intentional.
A10: TC09 | B10: Plaintext Credentials (dummy) | C10: Dummy credential-shaped string hard-coded in a Terraform local; value is non-sensitive test data. | D10: Vulnerable | E10: 7/0 (Checkov run with --framework terraform; secrets framework not run) | F10: FN | G10: 0 findings | H10: FN | I10: MEDIUM hard-coded secret finding in 3/3 runs (85/100). | J10: TP | K10: MEDIUM finding (PR #65). | L10: TP | M10: — | N10: PR #78, 277a730; hybrid PR #65 | O10: Checkov non-detection reflects pipeline configuration as much as tool capability. Explanation accuracy (state claims) to be scored in step 2.
A11: TC10 | B11: Excessive Azure IAM Permissions | C11: Custom role actions = ['*'] at subscription scope exceeds minimum. | D11: Vulnerable | E11: CKV_AZURE_39 (7/1) | F11: TP | G11: 0 findings | H11: FN | I11: HIGH wildcard-role finding in 3/3 runs; 2/3 runs added LOW TAG-001. | J11: TP | K11: Run 1: 2 × CRITICAL (40/100); rerun same commit: 1 × HIGH (70/100) (PR #66). | L11: TP | M11: AI TAG-001 on azurerm_role_definition (resource has no tags) — AI false positive in 2/3 runs. | N11: PR #79, bd8a61f; hybrid PR #66 (2 attempts) | O11: Matrix 'critical' reflected hybrid run 1 only.
A12: TC11 | B12: Multi-file, context-dependent weakness | C12: Wildcard role vs read-only actions documented in tc11_requirements.tf. | D12: Vulnerable | E12: CKV_AZURE_39 (7/1) | F12: TP | G12: 0 findings | H12: FN | I12: HIGH finding in 3/3 runs; all 3 cite tc11_requirements.tf. | J12: TP | K12: HIGH finding ×2, cited Checkov (PR #67). | L12: TP | M12: — | N12: PR #80, 3dd9a04; hybrid PR #67 (2 attempts) | O12: Construct validity: the wildcard alone triggers detection, so this does not isolate multi-file reasoning. Confluence heading 'AI-only (B)' is wrong — evidence is Condition C.
A13: TC12 | B13: Legitimate Public HTTPS Service | C13: Public TCP/443 is intentional; exposure alone is not a vulnerability. | D13: Legitimate | E13: 11 passed / 0 failed | F13: TN | G13: AVD-AZU-0047 (CRITICAL) on the intended rule | H13: CONTEXT | I13: Varied: run 1 blocked (HIGH + MEDIUM SEC-001 + LOW TAG-001, 50/100); run 2 LOW TAG-001 only (95); run 3 none (100), said SEC-001 justified and TAG-001 n/a. | J13: CONTEXT | K13: MEDIUM SEC-001 scope concern (PR #68). | L13: CONTEXT | M13: AI TAG-001 on azurerm_network_security_rule (resource has no tags) — AI false positive in 2/3 runs. | N13: PR #81, 9cee1fe; hybrid PR #68 | O13: Decide whether the shared-NSG/wildcard-destination scope concern counts as a separate weakness; until then tfsec and AI are CONTEXT.

Sheet Summary
A1: Descriptive counts (formula-driven from 'Verified Matrix')
A3: Measure | B3: Checkov | C3: tfsec | D3: AI independent | E3: AI hybrid (Cond. C) | F3: Definition / denominator
A4: Vulnerable cases (denominator) | B4: =COUNTIF('Verified Matrix'!$D$2:$D$13,"Vulnerable") -> 10 | C4: =COUNTIF('Verified Matrix'!$D$2:$D$13,"Vulnerable") -> 10 | D4: =COUNTIF('Verified Matrix'!$D$2:$D$13,"Vulnerable") -> 10 | E4: =COUNTIF('Verified Matrix'!$D$2:$D$13,"Vulnerable") -> 10 | F4: TC02–TC11
A5: Target condition detected (TP) | B5: =COUNTIFS('Verified Matrix'!$D$2:$D$13,"Vulnerable",'Verified Matrix'!$F$2:$F$13,"TP") -> 5 | C5: =COUNTIFS('Verified Matrix'!$D$2:$D$13,"Vulnerable",'Verified Matrix'!$H$2:$H$13,"TP") -> 4 | D5: =COUNTIFS('Verified Matrix'!$D$2:$D$13,"Vulnerable",'Verified Matrix'!$J$2:$J$13,"TP") -> 9 | E5: =COUNTIFS('Verified Matrix'!$D$2:$D$13,"Vulnerable",'Verified Matrix'!$L$2:$L$13,"TP") -> 10 | F5: Normalised: one detection per case regardless of rule count
A6: Target condition missed (FN) | B6: =COUNTIFS('Verified Matrix'!$D$2:$D$13,"Vulnerable",'Verified Matrix'!$F$2:$F$13,"FN") -> 5 | C6: =COUNTIFS('Verified Matrix'!$D$2:$D$13,"Vulnerable",'Verified Matrix'!$H$2:$H$13,"FN") -> 6 | D6: =COUNTIFS('Verified Matrix'!$D$2:$D$13,"Vulnerable",'Verified Matrix'!$J$2:$J$13,"FN") -> 0 | E6: =COUNTIFS('Verified Matrix'!$D$2:$D$13,"Vulnerable",'Verified Matrix'!$L$2:$L$13,"FN") -> 0
A7: Inconsistent across runs (PARTIAL) | B7: =COUNTIFS('Verified Matrix'!$D$2:$D$13,"Vulnerable",'Verified Matrix'!$F$2:$F$13,"PARTIAL") -> 0 | C7: =COUNTIFS('Verified Matrix'!$D$2:$D$13,"Vulnerable",'Verified Matrix'!$H$2:$H$13,"PARTIAL") -> 0 | D7: =COUNTIFS('Verified Matrix'!$D$2:$D$13,"Vulnerable",'Verified Matrix'!$J$2:$J$13,"PARTIAL") -> 1 | E7: =COUNTIFS('Verified Matrix'!$D$2:$D$13,"Vulnerable",'Verified Matrix'!$L$2:$L$13,"PARTIAL") -> 0 | F7: AI only: TC08
A8: Detection rate (TP / vulnerable cases) | B8: =IFERROR(B5/B4,0) -> 0.5 | C8: =IFERROR(C5/C4,0) -> 0.4 | D8: =IFERROR(D5/D4,0) -> 0.9 | E8: =IFERROR(E5/E4,0) -> 1 | F8: Descriptive only; n = 10 constructed cases, not a population estimate
A9: Secure baseline TC01 — clean (TN) | B9: =COUNTIFS('Verified Matrix'!$D$2:$D$13,"Secure",'Verified Matrix'!$F$2:$F$13,"TN") -> 1 | C9: =COUNTIFS('Verified Matrix'!$D$2:$D$13,"Secure",'Verified Matrix'!$H$2:$H$13,"TN") -> 1 | D9: =COUNTIFS('Verified Matrix'!$D$2:$D$13,"Secure",'Verified Matrix'!$J$2:$J$13,"TN") -> 1 | E9: =COUNTIFS('Verified Matrix'!$D$2:$D$13,"Secure",'Verified Matrix'!$L$2:$L$13,"TN") -> 0 | F9: 1 case
A10: Secure baseline TC01 — unverified | B10: =COUNTIFS('Verified Matrix'!$D$2:$D$13,"Secure",'Verified Matrix'!$F$2:$F$13,"UNVERIFIED") -> 0 | C10: =COUNTIFS('Verified Matrix'!$D$2:$D$13,"Secure",'Verified Matrix'!$H$2:$H$13,"UNVERIFIED") -> 0 | D10: =COUNTIFS('Verified Matrix'!$D$2:$D$13,"Secure",'Verified Matrix'!$J$2:$J$13,"UNVERIFIED") -> 0 | E10: =COUNTIFS('Verified Matrix'!$D$2:$D$13,"Secure",'Verified Matrix'!$L$2:$L$13,"UNVERIFIED") -> 1 | F10: Hybrid TC01 evidence conflict
A11: Legitimate TC12 — no finding (TN) | B11: =COUNTIFS('Verified Matrix'!$D$2:$D$13,"Legitimate",'Verified Matrix'!$F$2:$F$13,"TN") -> 1 | C11: =COUNTIFS('Verified Matrix'!$D$2:$D$13,"Legitimate",'Verified Matrix'!$H$2:$H$13,"TN") -> 0 | D11: =COUNTIFS('Verified Matrix'!$D$2:$D$13,"Legitimate",'Verified Matrix'!$J$2:$J$13,"TN") -> 0 | E11: =COUNTIFS('Verified Matrix'!$D$2:$D$13,"Legitimate",'Verified Matrix'!$L$2:$L$13,"TN") -> 0 | F11: 1 case
A12: Legitimate TC12 — context-sensitive (CONTEXT) | B12: =COUNTIFS('Verified Matrix'!$D$2:$D$13,"Legitimate",'Verified Matrix'!$F$2:$F$13,"CONTEXT") -> 0 | C12: =COUNTIFS('Verified Matrix'!$D$2:$D$13,"Legitimate",'Verified Matrix'!$H$2:$H$13,"CONTEXT") -> 1 | D12: =COUNTIFS('Verified Matrix'!$D$2:$D$13,"Legitimate",'Verified Matrix'!$J$2:$J$13,"CONTEXT") -> 1 | E12: =COUNTIFS('Verified Matrix'!$D$2:$D$13,"Legitimate",'Verified Matrix'!$L$2:$L$13,"CONTEXT") -> 1 | F12: Pending researcher decision
A15: Union and overlap (vulnerable cases)
A16: Detected by Checkov OR tfsec | B16: =SUMPRODUCT(('Verified Matrix'!$D$2:$D$13="Vulnerable")*((('Verified Matrix'!$F$2:$F$13="TP")+('Verified Matrix'!$H$2:$H$13="TP"))>0)) -> 8 | F16: Scanner union
A17: Detected by AI independent (TP) but by neither scanner | B17: =SUMPRODUCT(('Verified Matrix'!$D$2:$D$13="Vulnerable")*('Verified Matrix'!$J$2:$J$13="TP")*('Verified Matrix'!$F$2:$F$13<>"TP")*('Verified Matrix'!$H$2:$H$13<>"TP")) -> 1 | F17: TC09 (TC08 is PARTIAL)
A18: Detected by a scanner but not by AI independent (TP) | B18: =SUMPRODUCT(('Verified Matrix'!$D$2:$D$13="Vulnerable")*(((('Verified Matrix'!$F$2:$F$13="TP")+('Verified Matrix'!$H$2:$H$13="TP"))>0))*('Verified Matrix'!$J$2:$J$13<>"TP")) -> 0 | F18: None expected
A19: Missed by all three | B19: =SUMPRODUCT(('Verified Matrix'!$D$2:$D$13="Vulnerable")*('Verified Matrix'!$F$2:$F$13<>"TP")*('Verified Matrix'!$H$2:$H$13<>"TP")*('Verified Matrix'!$J$2:$J$13<>"TP")*('Verified Matrix'!$J$2:$J$13<>"PARTIAL")) -> 0
A21: Notes: counts are descriptive for 12 controlled fixtures. Alert counts are not quality measures; scanner rules for one condition are normalised to one detection. AI independent classification uses 3 identical runs per case.

Sheet Independent AI Runs
A1: Test case | B1: PR | C1: Run ID | D1: Event | E1: Started (UTC) | F1: Commit | G1: Condition (metadata) | H1: Scanner findings supplied to AI | I1: AI output status | J1: Confirmed findings | K1: Other findings (not in PR comment) | L1: Operational score | M1: Verdict
A2: TC01 | B2: 70 | C2: 38404582550 | D2: pull_request | E2: 2026-10-13 13:23:46 | F2: 92ab884 | G2: INDEPENDENT | H2: FALSE | I2: parsed | J2: none | K2: FALSE_POSITIVE · INFORMATIONAL · Private DNS zone name extraction via split() index — plausible concern, not a defect | L2: 100 | M2: APPROVE
A3: TC01 | B3: 70 | C3: 38405003190 | D3: workflow_dispatch | E3: 2026-10-13 13:26:53 | F3: 92ab884 | G3: INDEPENDENT | H3: FALSE | I3: parsed | J3: none | K3: none | L3: 100 | M3: APPROVE
A4: TC01 | B4: 70 | C4: 38405111880 | D4: workflow_dispatch | E4: 2026-10-13 13:27:41 | F4: 92ab884 | G4: INDEPENDENT | H4: FALSE | I4: parsed | J4: none | K4: FALSE_POSITIVE · INFORMATIONAL · NSG deny-all outbound rule may be flagged as redundant by scanners FALSE_POSITIVE · INFORMATIONAL · DDoS Protection Standard not enabled — inapplicable to research workload FALSE_POSITIVE · INFORMATIONAL · Subnet NSG association is correctly configured | L4: 100 | M4: APPROVE
A5: TC02 | B5: 71 | C5: 38404584887 | D5: pull_request | E5: 2026-10-13 13:23:46 | F5: 3eda6f7 | G5: INDEPENDENT | H5: FALSE | I5: parsed | J5: HIGH · SECURITY_VULNERABILITY · Unrestricted inbound SSH access permitted from any source address | K5: none | L5: 70 | M5: APPROVE_WITH_COMMENTS
A6: TC02 | B6: 71 | C6: 38405012851 | D6: workflow_dispatch | E6: 2026-10-13 13:26:59 | F6: 3eda6f7 | G6: INDEPENDENT | H6: FALSE | I6: parsed | J6: HIGH · SECURITY_VULNERABILITY · Inbound SSH (port 22) permitted from any source address (0.0.0.0/0) | K6: none | L6: 70 | M6: APPROVE_WITH_COMMENTS
A7: TC02 | B7: 71 | C7: 38405121064 | D7: workflow_dispatch | E7: 2026-10-13 13:27:45 | F7: 3eda6f7 | G7: INDEPENDENT | H7: FALSE | I7: parsed | J7: HIGH · SECURITY_VULNERABILITY · NSG permits inbound SSH (TCP/22) from any source (0.0.0.0/0) | K7: none | L7: 70 | M7: APPROVE_WITH_COMMENTS
A8: TC03 | B8: 72 | C8: 38404589228 | D8: pull_request | E8: 2026-10-13 13:23:47 | F8: 27789d9 | G8: INDEPENDENT | H8: FALSE | I8: parsed | J8: HIGH · SECURITY_VULNERABILITY · RDP (TCP/3389) publicly accessible from any source address | K8: none | L8: 70 | M8: APPROVE_WITH_COMMENTS
A9: TC03 | B9: 72 | C9: 38405022162 | D9: workflow_dispatch | E9: 2026-10-13 13:27:00 | F9: 27789d9 | G9: INDEPENDENT | H9: FALSE | I9: parsed | J9: HIGH · SECURITY_VULNERABILITY · Unrestricted inbound RDP (port 3389) permitted from 0.0.0.0/0 | K9: none | L9: 70 | M9: APPROVE_WITH_COMMENTS
A10: TC03 | B10: 72 | C10: 38405130215 | D10: workflow_dispatch | E10: 2026-10-13 13:27:48 | F10: 27789d9 | G10: INDEPENDENT | H10: FALSE | I10: parsed | J10: HIGH · SECURITY_VULNERABILITY · Unrestricted inbound RDP access from any source (0.0.0.0/0) on port 3389 HIGH · POLICY_OR_COMPLIANCE · SEC-001 violation: public RDP exposure without documented policy justification | K10: none | L10: 40 | M10: DO_NOT_MERGE
A11: TC04 | B11: 73 | C11: 38404592498 | D11: pull_request | E11: 2026-10-13 13:23:50 | F11: cbc6855 | G11: INDEPENDENT | H11: FALSE | I11: parsed | J11: HIGH · SECURITY_VULNERABILITY · Unrestricted inbound HTTP (TCP/80) permitted from any source via NSG rule | K11: none | L11: 70 | M11: APPROVE_WITH_COMMENTS
A12: TC04 | B12: 73 | C12: 38405031009 | D12: workflow_dispatch | E12: 2026-10-13 13:27:06 | F12: cbc6855 | G12: INDEPENDENT | H12: FALSE | I12: parsed | J12: HIGH · SECURITY_VULNERABILITY · NSG allows unrestricted inbound HTTP (TCP/80) from any IPv4 address | K12: none | L12: 70 | M12: APPROVE_WITH_COMMENTS
A13: TC04 | B13: 73 | C13: 38405139458 | D13: workflow_dispatch | E13: 2026-10-13 13:27:53 | F13: cbc6855 | G13: INDEPENDENT | H13: FALSE | I13: parsed | J13: HIGH · SECURITY_VULNERABILITY · NSG rule permits unrestricted inbound HTTP (TCP/80) from any IPv4 source | K13: none | L13: 70 | M13: APPROVE_WITH_COMMENTS
... A22: TC07 | B22: 76 | C22: 38405166219 | D22: workflow_dispatch | E22: 2026-10-13 13:28:05 | F22: b6e93b7 | G22: INDEPENDENT | H22: FALSE | I22: parsed | J22: HIGH · SECURITY_VULNERABILITY · Storage account permits deprecated TLS 1.0 connections LOW · POLICY_OR_COMPLIANCE · Storage account missing mandatory tags: owner and cost-center | K22: NEEDS_CONTEXT · HIGH · Storage account may be publicly accessible with no network restriction | L22: 65 | M22: DO_NOT_MERGE
A23: TC08 | B23: 77 | C23: 38404605125 | D23: pull_request | E23: 2026-10-13 13:23:55 | F23: c86e4d5 | G23: INDEPENDENT | H23: FALSE | I23: AI step failed | J23: — | K23: Output rejected by validator: FALSE_POSITIVE/INFORMATIONAL 'No azurerm_monitor_diagnostic_setting configured for the NSG' with a policy mapping to a non-confirmed finding | L23: — | M23: —
A24: TC08 | B24: 77 | C24: 38405066857 | D24: workflow_dispatch | E24: 2026-10-13 13:27:23 | F24: c86e4d5 | G24: INDEPENDENT | H24: FALSE | I24: parsed | J24: none | K24: NEEDS_CONTEXT · MEDIUM · No diagnostic setting configured for the NSG resource FALSE_POSITIVE · INFORMATIONAL · Explicit outbound deny rule is intentional defense-in-depth, not redundant FALSE_POSITIVE · INFORMATIONAL · Private-only Log Analytics access is intentional; no client workload in TC01 scope | L24: 100 | M24: APPROVE
A25: TC08 | B25: 77 | C25: 38405174844 | D25: workflow_dispatch | E25: 2026-10-13 13:28:07 | F25: c86e4d5 | G25: INDEPENDENT | H25: FALSE | I25: parsed | J25: none | K25: NEEDS_CONTEXT · MEDIUM · No azurerm_monitor_diagnostic_setting configured for the NSG resource | L25: 100 | M25: APPROVE
A26: TC08 | B26: 77 | C26: 38405218950 | D26: workflow_dispatch | E26: 2026-10-13 13:28:40 | F26: c86e4d5 | G26: INDEPENDENT | H26: FALSE | I26: parsed | J26: MEDIUM · POLICY_OR_COMPLIANCE · No diagnostic setting configured to forward NSG logs to Log Analytics | K26: none | L26: 85 | M26: APPROVE
A27: TC09 | B27: 78 | C27: 38404607277 | D27: pull_request | E27: 2026-10-13 13:23:54 | F27: 277a730 | G27: INDEPENDENT | H27: FALSE | I27: parsed | J27: MEDIUM · SECURITY_VULNERABILITY · Hardcoded secret value embedded in Terraform local in source-controlled file | K27: none | L27: 85 | M27: APPROVE
A28: TC09 | B28: 78 | C28: 38405075984 | D28: workflow_dispatch | E28: 2026-10-13 13:27:28 | F28: 277a730 | G28: INDEPENDENT | H28: FALSE | I28: parsed | J28: MEDIUM · SECURITY_VULNERABILITY · Hardcoded credential-shaped string stored as a plaintext Terraform local in source control | K28: none | L28: 85 | M28: APPROVE
A29: TC09 | B29: 78 | C29: 38405183161 | D29: workflow_dispatch | E29: 2026-10-13 13:28:12 | F29: 277a730 | G29: INDEPENDENT | H29: FALSE | I29: parsed | J29: MEDIUM · SECURITY_VULNERABILITY · Hardcoded secret-like string embedded in Terraform local value | K29: none | L29: 85 | M29: APPROVE
A30: TC10 | B30: 79 | C30: 38404612132 | D30: pull_request | E30: 2026-10-13 13:23:59 | F30: bd8a61f | G30: INDEPENDENT | H30: FALSE | I30: parsed | J30: HIGH · SECURITY_VULNERABILITY · Custom role definition grants unrestricted wildcard ('*') permissions at subscription scope LOW · POLICY_OR_COMPLIANCE · Custom role definition is missing mandatory tags required by TAG-001 | K30: none | L30: 65 | M30: DO_NOT_MERGE
A31: TC10 | B31: 79 | C31: 38405084901 | D31: workflow_dispatch | E31: 2026-10-13 13:27:31 | F31: bd8a61f | G31: INDEPENDENT | H31: FALSE | I31: parsed | J31: HIGH · SECURITY_VULNERABILITY · Custom role definition grants wildcard (*) permissions at subscription scope | K31: none | L31: 70 | M31: APPROVE_WITH_COMMENTS
A32: TC10 | B32: 79 | C32: 38405192342 | D32: workflow_dispatch | E32: 2026-10-13 13:28:16 | F32: bd8a61f | G32: INDEPENDENT | H32: FALSE | I32: parsed | J32: HIGH · SECURITY_VULNERABILITY · Subscription-scoped wildcard role definition grants unrestricted ARM permissions LOW · POLICY_OR_COMPLIANCE · Custom role definition missing mandatory tags required by TAG-001 | K32: none | L32: 65 | M32: DO_NOT_MERGE
A33: TC11 | B33: 80 | C33: 38404613836 | D33: pull_request | E33: 2026-10-13 13:23:57 | F33: 3dd9a04 | G33: INDEPENDENT | H33: FALSE | I33: parsed | J33: HIGH · SECURITY_VULNERABILITY · Custom RBAC role grants wildcard (*) permissions at subscription scope, violating least privilege | K33: none | L33: 70 | M33: APPROVE_WITH_COMMENTS
A34: TC11 | B34: 80 | C34: 38405093864 | D34: workflow_dispatch | E34: 2026-10-13 13:27:32 | F34: 3dd9a04 | G34: INDEPENDENT | H34: FALSE | I34: parsed | J34: HIGH · SECURITY_VULNERABILITY · Custom role grants wildcard subscription-scope permissions far exceeding documented task requirements | K34: none | L34: 70 | M34: APPROVE_WITH_COMMENTS
A35: TC11 | B35: 80 | C35: 38405200842 | D35: workflow_dispatch | E35: 2026-10-13 13:28:23 | F35: 3dd9a04 | G35: INDEPENDENT | H35: FALSE | I35: parsed | J35: HIGH · SECURITY_VULNERABILITY · Custom role definition grants wildcard subscription-scope permissions far exceeding documented task requirements | K35: none | L35: 70 | M35: APPROVE_WITH_COMMENTS
... A38: TC12 | B38: 81 | C38: 38405210047 | D38: workflow_dispatch | E38: 2026-10-13 13:28:25 | F38: 9cee1fe | G38: INDEPENDENT | H38: FALSE | I38: parsed | J38: none | K38: NEEDS_CONTEXT · MEDIUM · AllowPublicHTTPS-TC12 rule uses wildcard destination address prefix FALSE_POSITIVE · INFORMATIONAL · Public inbound HTTPS rule is explicitly justified — not a SEC-001 violation FALSE_POSITIVE · INFORMATIONAL · azurerm_network_security_rule does not support tags — TAG-001 not applicable | L38: 100 | M38: APPROVE
A40: Source: experiment-metadata.json and ai_output.json in each prom06-INDEPENDENT-<run_id> artifact (downloaded by AB, 13 Oct 2026). Model: claude-sonnet-4-6 (hard-coded in ai/review_runner.py; not recorded in metadata); no temperature set.

Sheet Scanner Results
A1: Test case | B1: Checkov passed | C1: Checkov failed | D1: Checkov failed check IDs | E1: tfsec findings (rule · severity · resource) | F1: Identical across independent runs | G1: Matches local reproduction | H1: Matches earlier Condition C PR comment
A2: TC01 | B2: 7 | C2: 0 | D2: none | E2: none | F2: Yes (3/3; TC08 4/4) | G2: Yes | H2: Yes
A3: TC02 | B3: 7 | C3: 0 | D3: none | E3: AVD-AZU-0047 · CRITICAL · azurerm_network_security_group.nsg AVD-AZU-0050 · CRITICAL · azurerm_network_security_group.nsg | F3: Yes (3/3; TC08 4/4) | G3: Yes | H3: Yes
A4: TC03 | B4: 7 | C4: 0 | D4: none | E4: AVD-AZU-0048 · CRITICAL · azurerm_network_security_group.nsg AVD-AZU-0047 · CRITICAL · azurerm_network_security_group.nsg | F4: Yes (3/3; TC08 4/4) | G4: Yes | H4: Yes
A5: TC04 | B5: 7 | C5: 0 | D5: none | E5: AVD-AZU-0047 · CRITICAL · azurerm_network_security_group.nsg | F5: Yes (3/3; TC08 4/4) | G5: Yes | H5: Yes
A6: TC05 | B6: 6 | C6: 1 | D6: CKV2_AZURE_31 | E6: none | F6: Yes (3/3; TC08 4/4) | G6: Yes | H6: Yes
A7: TC06 | B7: 5 | C7: 2 | D7: CKV_AZURE_183, CKV_AZURE_182 | E7: none | F7: Yes (3/3; TC08 4/4) | G7: Yes | H7: Yes
A8: TC07 | B8: 11 | C8: 11 | D8: CKV_AZURE_59, CKV_AZURE_206, CKV_AZURE_190, CKV_AZURE_33, CKV_AZURE_44, CKV2_AZURE_47, CKV2_AZURE_38, CKV2_AZURE_40, CKV2_AZURE_33, CKV2_AZURE_41, CKV2_AZURE_1 | E8: AVD-AZU-0011 · CRITICAL · azurerm_storage_account.tc07_storage | F8: Yes (3/3; TC08 4/4) | G8: Yes | H8: Yes
A9: TC08 | B9: 7 | C9: 0 | D9: none | E9: none | F9: Yes (3/3; TC08 4/4) | G9: Yes | H9: Yes
A10: TC09 | B10: 7 | C10: 0 | D10: none | E10: none | F10: Yes (3/3; TC08 4/4) | G10: Yes | H10: Yes
A11: TC10 | B11: 7 | C11: 1 | D11: CKV_AZURE_39 | E11: none | F11: Yes (3/3; TC08 4/4) | G11: Yes | H11: Yes
A12: TC11 | B12: 7 | C12: 1 | D12: CKV_AZURE_39 | E12: none | F12: Yes (3/3; TC08 4/4) | G12: Yes | H12: Yes
A13: TC12 | B13: 11 | C13: 0 | D13: none | E13: AVD-AZU-0047 · CRITICAL · azurerm_network_security_rule.tc12_public_https | F13: Yes (3/3; TC08 4/4) | G13: Yes | H13: Yes
A15: Local reproduction: Checkov 3.3.1 (--framework terraform --output json) and tfsec v1.28.14 (--format json) on each indep-tc branch, 13 Oct 2026. Checkov OSS JSON reports no severity. Probe: changing TC02 source '0.0.0.0/0' to '*' makes CKV_AZURE_10 fail.

Sheet Hybrid Runs (Condition C)
A1: Test case | B1: PR | C1: Head commit | D1: Run ID | E1: Run attempts | F1: AI result (PR comment) | G1: Scanner IDs cited by AI | H1: Notes
A2: TC01 | B2: #46 | C2: 0003ccf | D2: 37804553671 | E2: 1 | F2: 55/100 DO_NOT_MERGE: MEDIUM TAG-001, MEDIUM LOG-001 confirmed; context note on missing explicit NSG rules | G2: none (no scanner context in code at that time) | H2: Older fixture (no tags/logging); later baseline changed
A3: TC01 | B3: #55 | C3: aea09b1 | D3: 37941043133 | E3: 1 | F3: Screenshot shows 100/100 clean, but PR changed only PROM06-TC-01.md so AI should have been skipped; comment posted 11 min before scanner comments | G3: — | H3: Not traceable to its own run — UNVERIFIED
A4: TC02 | B4: #56 | C4: 1112b8b | D4: 37949921520 | E4: 1 | F4: 70/100: CRITICAL SSH | G4: AVD-AZU-0047, AVD-AZU-0050
A5: TC03 | B5: #57 | C5: 4d213c6 | D5: 38240217182 | E5: 1 | F5: 70/100: CRITICAL RDP | G5: AVD-AZU-0048, AVD-AZU-0047
A6: TC04 | B6: #58 | C6: 4d2f880 | D6: 38241873851 | E6: 1 | F6: 70/100: HIGH HTTP | G6: AVD-AZU-0047 | H6: PR closed unmerged
A7: TC05 | B7: #59 | C7: dad9df3 | D7: 38243286069 | E7: 1 | F7: 85/100: MEDIUM NET-001 | G7: CKV2_AZURE_31
A8: TC06 | B8: #61 | C8: 1ea2c15 | D8: 38245294170 | E8: 1 | F8: 85/100: MEDIUM NET-002 | G8: CKV_AZURE_183, CKV_AZURE_182 | H8: #60 was an earlier TC06 variant
A9: TC07 | B9: #63 | C9: de8549e | D9: 38281784140 | E9: 1 | F9: 25/100: CRITICAL TLS, MEDIUM TAG-001, HIGH public network | G9: AVD-AZU-0011, CKV_AZURE_44, CKV_AZURE_59, CKV2_AZURE_47/33/40 | H9: #62 web-app variant not used
A10: TC08 | B10: #64 | C10: 7cb9014 | D10: 38283490262 | E10: 1 | F10: 85/100: MEDIUM LOG-001 | G10: none (scanners clean)
A11: TC09 | B11: #65 | C11: eca6e99 | D11: 38285110293 | E11: 3 | F11: 85/100: MEDIUM hard-coded secret | G11: none (scanners clean) | H11: 3 attempts; claimed value would be stored in state
A12: TC10 | B12: #66 | C12: dd05ba4 | D12: 38287543507 | E12: 2 | F12: Attempt 1: 40/100, 2 × CRITICAL; attempt 2 (13 Oct): 70/100, 1 × HIGH | G12: CKV_AZURE_39 | H12: Explains matrix severity conflict
A13: TC11 | B13: #67 | C13: 960dac3 | D13: 38288761497 | E13: 2 | F13: Both attempts 70/100: 1 × HIGH | G13: CKV_AZURE_39 (listed as a 'policy mapping' in attempt 2) | H13: Confluence heading 'AI-only (B)' incorrect
A14: TC12 | B14: #68 | C14: 709316c | D14: 38289955785 | E14: 1 | F14: 85/100: MEDIUM SEC-001 scope concern | G14: AVD-AZU-0047
A16: Runs on 9–12 Oct used workflow default Condition C with build_scanner_context() (added 9 Oct 12:47, commit 732083d), so the AI prompt contained normalised scanner findings. Run IDs/attempts from GitHub Actions API.

Sheet Decisions & Caveats
A1: # | B1: Item | C1: Proposed treatment | D1: AB decision
A2: 1 | B2: TC12 tfsec AVD-AZU-0047 and AI SEC-001: count the shared-NSG / wildcard-destination scope as a separate weakness? | C2: Keep as CONTEXT; report both readings (FP against TC12-GT-01 vs valid scope concern). | D2: Agreed — proposed treatment adopted (AB, 13 Oct 2026)
A3: 2 | B3: TC08 AI result | C3: Report PARTIAL: raised 4/4, confirmed 1/3 successful runs; treat as classification instability. | D3: Agreed — proposed treatment adopted (AB, 13 Oct 2026)
A4: 3 | B4: TC01 hybrid result | C4: Report as UNVERIFIED; use independent TC01 (clean 3/3) as the baseline result; disclose baseline evolution. | D4: Agreed — proposed treatment adopted (AB, 13 Oct 2026)
A5: 4 | B5: TC11 construct | C5: Count detections, but state the case does not isolate multi-file reasoning (wildcard alone triggers CKV_AZURE_39). | D5: Agreed — proposed treatment adopted (AB, 13 Oct 2026)
A6: 5 | B6: AI TAG-001 findings on non-taggable resources (TC10, TC12) | C6: Count as AI false positives (unrelated to target). | D6: Agreed — proposed treatment adopted (AB, 13 Oct 2026)
A7: 6 | B7: Input asymmetry: only the AI receives ai/policy.md (NET-001, NET-002, LOG-001, SEC-001, TAG-001) | C7: Report as a fairness/validity limitation, especially for TC05, TC06, TC08, TC12. | D7: Agreed — proposed treatment adopted (AB, 13 Oct 2026)
A8: 7 | B8: Severity comparison | C8: Do not compare severities across tools; report AI severity variability only. | D8: Agreed — proposed treatment adopted (AB, 13 Oct 2026)
A9: 8 | B9: Ground truth source | C9: Use Confluence v72 per-case ground truth (more specific than GT Matrix v1.0); note GT v1.0 TC04 wording differs. | D9: Agreed — proposed treatment adopted (AB, 13 Oct 2026)
A10: 9 | B10: Checkov TC02–TC04 misses | C10: Report as reproducible rule-matching limitation with the local probe as evidence. | D10: Agreed — proposed treatment adopted (AB, 13 Oct 2026)
A11: 10 | B11: Close PRs #56–#81 without merging after sign-off | C11: — | D11: Agreed — proposed treatment adopted (AB, 13 Oct 2026)

Sheet Scoring Rules
A1: AI explanation and remediation quality — operational scoring rules
A2: Rubric dimensions and 0–2 scale come from the TC01–TC12 Ground-Truth Matrix (remediation-quality rubric). The operational definitions below were written on 13 Oct 2026 to make the rubric applicable consistently. They were written AFTER the AI outputs had been read, by an AI assistant (Claude) acting as scorer; see the disclosure at the bottom.
A5: Dimension | B5: 2 = full | C5: 1 = partial | D5: 0 = none / wrong
A6: D Detection correctness (vulnerable case) | B6: Target condition raised as CONFIRMED on the correct resource. | C6: Target raised but as NEEDS_CONTEXT (hidden from PR comment), or only partly identified. | D6: Target not raised, classified FALSE_POSITIVE, or run failed validation.
A7: D Detection correctness (non-vulnerable case) | B7: No confirmed finding against the acceptable configuration. | C7: Only a LOW or unrelated confirmed finding. | D7: Blocks (fails the gate on) the acceptable configuration.
A8: E Explanation accuracy | B8: Every technical and policy claim is correct. | C8: Contains one or more inaccurate claims, or maps the finding to an inapplicable policy (e.g. SEC-001 'public exposure' applied to IAM, TLS or secrets; tags claimed on a non-taggable resource type). | D8: Core explanation materially wrong.
A9: I Impact explanation | B9: Specific consequence for this configuration (who can reach/do what). | C9: Generic or partly inaccurate impact. | D9: Missing.
A10: R Remediation quality | B10: Correct, actionable, addresses the root cause and would yield the ground-truth secure state. | C10: Partly correct, or misses part of the secure state, or adds questionable advice. | D10: Wrong or absent.
A11: C Context awareness | B11: Correctly uses related resources/files (associations, requirements, other files). | C11: Some context used but incomplete or misread. | D11: Ignores relevant context.
A12: U Developer usefulness | B12: A developer could act on the PR comment immediately; no noise. | C12: Useful but with noise: extra false or duplicate CONFIRMED findings. | D12: Misleading or useless in the PR comment: target hidden (NEEDS_CONTEXT is not shown), run failed, or legitimate configuration blocked.
A14: Application notes
A15: 1. Scope: vulnerable cases (TC02–TC11) are scored on all six dimensions (max 12). Non-vulnerable cases (TC01, TC12) are scored on D, E and U only (max 6); I, R and C are 'n/a'.
A16: 2. Each run is scored separately (3 runs per case; 4 for TC08 because one PR run failed validation and a fourth dispatch was made).
A17: 3. Only the AI output of the INDEPENDENT condition is scored (scanner_findings_supplied_to_ai = false). Hybrid (Condition C) outputs are not scored here.
A18: 4. Policy mis-mapping is penalised under E only (not U) to avoid double counting; it is also flagged separately in column O of 'AI Quality Scoring' so analysis can exclude it.
A19: 5. Disclosure / validity threat: the scorer is an AI assistant that read all outputs before writing these rules. To mitigate, AB should independently score the stratified sample on 'Inter-rater Check' before results are reported; agreement is calculated there.
A20: 6. TC13–TC15 (added 13 Oct 2026) are not yet scored: their full ai_output.json artefacts still need to be downloaded.

Sheet AI Quality Scoring
A1: TC | B1: Run | C1: Run ID | D1: Event | E1: Ground truth | F1: Target status in AI output | G1: D | H1: E | I1: I | J1: R | K1: C | L1: U | M1: Total | N1: Max | O1: Score % | P1: Policy mis-map? | Q1: Noise in PR comment? | R1: Scorer justification
A2: TC01 | B2: 1 | C2: 38404582550 | D2: pull_request | E2: Not vulnerable | F2: No confirmed findings | G2: 2 | H2: 2 | I2: n/a | J2: n/a | K2: n/a | L2: 2 | M2: =SUM(G2:L2) -> 6 | N2: =IF(E2="Vulnerable",12,6) -> 6 | O2: =M2/N2 -> 1 | P2: N | Q2: N | R2: Clean. One FALSE_POSITIVE informational note (DNS zone name split) correctly dismissed; not shown in PR comment.
A3: TC01 | B3: 2 | C3: 38405003190 | D3: workflow_dispatch | E3: Not vulnerable | F3: No findings | G3: 2 | H3: 2 | I3: n/a | J3: n/a | K3: n/a | L3: 2 | M3: =SUM(G3:L3) -> 6 | N3: =IF(E3="Vulnerable",12,6) -> 6 | O3: =M3/N3 -> 1 | P3: N | Q3: N | R3: Clean; no findings.
A4: TC01 | B4: 3 | C4: 38405111880 | D4: workflow_dispatch | E4: Not vulnerable | F4: No confirmed findings | G4: 2 | H4: 2 | I4: n/a | J4: n/a | K4: n/a | L4: 2 | M4: =SUM(G4:L4) -> 6 | N4: =IF(E4="Vulnerable",12,6) -> 6 | O4: =M4/N4 -> 1 | P4: N | Q4: N | R4: Clean. Three FALSE_POSITIVE informational notes, all correct dismissals (outbound deny, DDoS not applicable, NSG association present).
A5: TC02 | B5: 1 | C5: 38404584887 | D5: pull_request | E5: Vulnerable | F5: CONFIRMED | G5: 2 | H5: 2 | I5: 2 | J5: 2 | K5: 2 | L5: 2 | M5: =SUM(G5:L5) -> 12 | N5: =IF(E5="Vulnerable",12,6) -> 12 | O5: =M5/N5 -> 1 | P5: N | Q5: N | R5: SSH 22 from 0.0.0.0/0 identified on the correct rule; specific internet brute-force impact; restrict source to approved CIDR/Bastion; uses NSG–subnet association.
A6: TC02 | B6: 2 | C6: 38405012851 | D6: workflow_dispatch | E6: Vulnerable | F6: CONFIRMED | G6: 2 | H6: 2 | I6: 2 | J6: 2 | K6: 2 | L6: 2 | M6: =SUM(G6:L6) -> 12 | N6: =IF(E6="Vulnerable",12,6) -> 12 | O6: =M6/N6 -> 1 | P6: N | Q6: N | R6: As run 1; accurate and actionable.
A7: TC02 | B7: 3 | C7: 38405121064 | D7: workflow_dispatch | E7: Vulnerable | F7: CONFIRMED | G7: 2 | H7: 2 | I7: 2 | J7: 2 | K7: 2 | L7: 2 | M7: =SUM(G7:L7) -> 12 | N7: =IF(E7="Vulnerable",12,6) -> 12 | O7: =M7/N7 -> 1 | P7: N | Q7: N | R7: As run 1; accurate and actionable.
A8: TC03 | B8: 1 | C8: 38404589228 | D8: pull_request | E8: Vulnerable | F8: CONFIRMED | G8: 2 | H8: 2 | I8: 2 | J8: 2 | K8: 2 | L8: 2 | M8: =SUM(G8:L8) -> 12 | N8: =IF(E8="Vulnerable",12,6) -> 12 | O8: =M8/N8 -> 1 | P8: N | Q8: N | R8: RDP 3389 from any source; SEC-001 mapping appropriate (public exposure); remediation restricts source / Bastion.
A9: TC03 | B9: 2 | C9: 38405022162 | D9: workflow_dispatch | E9: Vulnerable | F9: CONFIRMED | G9: 2 | H9: 2 | I9: 2 | J9: 2 | K9: 2 | L9: 2 | M9: =SUM(G9:L9) -> 12 | N9: =IF(E9="Vulnerable",12,6) -> 12 | O9: =M9/N9 -> 1 | P9: N | Q9: N | R9: As run 1.
A10: TC03 | B10: 3 | C10: 38405130215 | D10: workflow_dispatch | E10: Vulnerable | F10: CONFIRMED | G10: 2 | H10: 2 | I10: 2 | J10: 2 | K10: 2 | L10: 1 | M10: =SUM(G10:L10) -> 11 | N10: =IF(E10="Vulnerable",12,6) -> 12 | O10: =M10/N10 -> 0.91666667 | P10: N | Q10: Y | R10: Target correct, but a second CONFIRMED HIGH finding (F-002 'SEC-001 violation') duplicates F-001 — duplicate noise in the PR comment.
A11: TC04 | B11: 1 | C11: 38404592498 | D11: pull_request | E11: Vulnerable | F11: CONFIRMED | G11: 2 | H11: 2 | I11: 1 | J11: 1 | K11: 2 | L11: 2 | M11: =SUM(G11:L11) -> 10 | N11: =IF(E11="Vulnerable",12,6) -> 12 | O11: =M11/N11 -> 0.83333333 | P11: N | Q11: N | R11: HTTP 80 from any source identified; impact framed as generic exposure with no reference to unencrypted HTTP; remediation restricts source only, no HTTPS/redirect alternative.
A12: TC04 | B12: 2 | C12: 38405031009 | D12: workflow_dispatch | E12: Vulnerable | F12: CONFIRMED | G12: 2 | H12: 2 | I12: 1 | J12: 1 | K12: 2 | L12: 2 | M12: =SUM(G12:L12) -> 10 | N12: =IF(E12="Vulnerable",12,6) -> 12 | O12: =M12/N12 -> 0.83333333 | P12: N | Q12: N | R12: As run 1 (no unencrypted-transport reasoning, no HTTPS alternative).
A13: TC04 | B13: 3 | C13: 38405139458 | D13: workflow_dispatch | E13: Vulnerable | F13: CONFIRMED | G13: 2 | H13: 2 | I13: 1 | J13: 1 | K13: 2 | L13: 2 | M13: =SUM(G13:L13) -> 10 | N13: =IF(E13="Vulnerable",12,6) -> 12 | O13: =M13/N13 -> 0.83333333 | P13: N | Q13: N | R13: As run 1.
A14: TC05 | B14: 1 | C14: 38404594354 | D14: pull_request | E14: Vulnerable | F14: CONFIRMED | G14: 2 | H14: 2 | I14: 2 | J14: 2 | K14: 2 | L14: 2 | M14: =SUM(G14:L14) -> 12 | N14: =IF(E14="Vulnerable",12,6) -> 12 | O14: =M14/N14 -> 1 | P14: N | Q14: N | R14: Missing subnet–NSG association found by cross-file reasoning (NSG exists, no association). Extra NEEDS_CONTEXT LOW note on DNS comment, not shown in PR comment.
A15: TC05 | B15: 2 | C15: 38405039302 | D15: workflow_dispatch | E15: Vulnerable | F15: CONFIRMED | G15: 2 | H15: 2 | I15: 2 | J15: 2 | K15: 2 | L15: 2 | M15: =SUM(G15:L15) -> 12 | N15: =IF(E15="Vulnerable",12,6) -> 12 | O15: =M15/N15 -> 1 | P15: N | Q15: N | R15: As run 1.
A16: TC05 | B16: 3 | C16: 38405149036 | D16: workflow_dispatch | E16: Vulnerable | F16: CONFIRMED | G16: 2 | H16: 2 | I16: 2 | J16: 2 | K16: 2 | L16: 2 | M16: =SUM(G16:L16) -> 12 | N16: =IF(E16="Vulnerable",12,6) -> 12 | O16: =M16/N16 -> 1 | P16: N | Q16: N | R16: As run 1 (severity MEDIUM rather than HIGH; does not affect rubric).
... A35: TC11 | B35: 3 | C35: 38405200842 | D35: workflow_dispatch | E35: Vulnerable | F35: CONFIRMED | G35: 2 | H35: 2 | I35: 2 | J35: 2 | K35: 2 | L35: 2 | M35: =SUM(G35:L35) -> 12 | N35: =IF(E35="Vulnerable",12,6) -> 12 | O35: =M35/N35 -> 1 | P35: N | Q35: N | R35: As run 2, without policy mis-mapping.
A36: TC12 | B36: 1 | C36: 38404619147 | D36: pull_request | E36: Not vulnerable | F36: CONFIRMED HIGH (blocks) | G36: 0 | H36: 1 | I36: n/a | J36: n/a | K36: n/a | L36: 0 | M36: =SUM(G36:L36) -> 1 | N36: =IF(E36="Vulnerable",12,6) -> 6 | O36: =M36/N36 -> 0.16666667 | P36: N | Q36: Y | R36: Legitimate public HTTPS treated as HIGH vulnerability; gate blocked (score 50). Also claims azurerm_network_security_rule supports tags (false).
A37: TC12 | B37: 2 | C37: 38405103514 | D37: workflow_dispatch | E37: Not vulnerable | F37: CONFIRMED LOW (tag) only | G37: 1 | H37: 1 | I37: n/a | J37: n/a | K37: n/a | L37: 1 | M37: =SUM(G37:L37) -> 3 | N37: =IF(E37="Vulnerable",12,6) -> 6 | O37: =M37/N37 -> 0.5 | P37: N | Q37: Y | R37: HTTPS exposure correctly not confirmed (destination-scope note as NEEDS_CONTEXT). Confirmed LOW TAG-001 finding is false: network security rules are not taggable.
A38: TC12 | B38: 3 | C38: 38405210047 | D38: workflow_dispatch | E38: Not vulnerable | F38: No confirmed findings | G38: 2 | H38: 2 | I38: n/a | J38: n/a | K38: n/a | L38: 2 | M38: =SUM(G38:L38) -> 6 | N38: =IF(E38="Vulnerable",12,6) -> 6 | O38: =M38/N38 -> 1 | P38: N | Q38: N | R38: Correctly accepted; correctly states rules are not taggable. Caveat: cites the fixture comment 'Ground truth: public TCP/443 ingress is intentional' — the test file cues the answer.
A39: Blue = scorer input (0–2). Totals and percentages are formulas. Source: ai_output.json in each prom06-INDEPENDENT-<run_id> artefact; rules on 'Scoring Rules'.
A41: Summary (formulas)
A42: Measure | G42: D | H42: E | I42: I | J42: R | K42: C | L42: U | O42: Score %
A43: Mean — vulnerable runs (TC02–TC11) | G43: =AVERAGEIFS(G$2:G$38,$E$2:$E$38,"Vulnerable") -> 1.8709677 | H43: =AVERAGEIFS(H$2:H$38,$E$2:$E$38,"Vulnerable") -> 1.6129032 | I43: =AVERAGEIFS(I$2:I$38,$E$2:$E$38,"Vulnerable") -> 1.7741935 | J43: =AVERAGEIFS(J$2:J$38,$E$2:$E$38,"Vulnerable") -> 1.8709677 | K43: =AVERAGEIFS(K$2:K$38,$E$2:$E$38,"Vulnerable") -> 1.9677419 | L43: =AVERAGEIFS(L$2:L$38,$E$2:$E$38,"Vulnerable") -> 1.7096774 | O43: =AVERAGEIFS(O$2:O$38,$E$2:$E$38,"Vulnerable") -> 0.90053763
A44: Mean — non-vulnerable runs (TC01, TC12) | G44: =AVERAGEIFS(G$2:G$38,$E$2:$E$38,"Not vulnerable") -> 1.5 | H44: =AVERAGEIFS(H$2:H$38,$E$2:$E$38,"Not vulnerable") -> 1.6666667 | I44: n/a | J44: n/a | K44: n/a | L44: =AVERAGEIFS(L$2:L$38,$E$2:$E$38,"Not vulnerable") -> 1.5 | O44: =AVERAGEIFS(O$2:O$38,$E$2:$E$38,"Not vulnerable") -> 0.77777778
A45: Runs with policy mis-mapping | G45: =COUNTIF(P$2:P$38,"Y")&" of "&COUNTA(P$2:P$38) -> 9 of 37
A46: Runs with noise in PR comment | G46: =COUNTIF(Q$2:Q$38,"Y")&" of "&COUNTA(Q$2:Q$38) -> 5 of 37
A47: Vulnerable runs scoring 2 on every dimension | G47: =SUMPRODUCT(($E$2:$E$38="Vulnerable")*(M$2:M$38=12))&" of "&COUNTIF($E$2:$E$38,"Vulnerable") -> 13 of 31
A49: Per test case
A50: TC | B50: Runs | C50: Mean D | D50: Mean E | E50: Mean U | F50: Mean R (vuln.) | G50: Mean score % | H50: Min score %
A51: TC01 | B51: =COUNTIF($A$2:$A$38,A51) -> 3 | C51: =AVERAGEIF($A$2:$A$38,A51,G$2:G$38) -> 2 | D51: =AVERAGEIF($A$2:$A$38,A51,H$2:H$38) -> 2 | E51: =AVERAGEIF($A$2:$A$38,A51,L$2:L$38) -> 2 | F51: =IFERROR(AVERAGEIF($A$2:$A$38,A51,J$2:J$38),"n/a") -> n/a | G51: =AVERAGEIF($A$2:$A$38,A51,O$2:O$38) -> 1 | H51: =_xlfn.MINIFS(O$2:O$38,$A$2:$A$38,A51) -> 1
A52: TC02 | B52: =COUNTIF($A$2:$A$38,A52) -> 3 | C52: =AVERAGEIF($A$2:$A$38,A52,G$2:G$38) -> 2 | D52: =AVERAGEIF($A$2:$A$38,A52,H$2:H$38) -> 2 | E52: =AVERAGEIF($A$2:$A$38,A52,L$2:L$38) -> 2 | F52: =IFERROR(AVERAGEIF($A$2:$A$38,A52,J$2:J$38),"n/a") -> 2 | G52: =AVERAGEIF($A$2:$A$38,A52,O$2:O$38) -> 1 | H52: =_xlfn.MINIFS(O$2:O$38,$A$2:$A$38,A52) -> 1
A53: TC03 | B53: =COUNTIF($A$2:$A$38,A53) -> 3 | C53: =AVERAGEIF($A$2:$A$38,A53,G$2:G$38) -> 2 | D53: =AVERAGEIF($A$2:$A$38,A53,H$2:H$38) -> 2 | E53: =AVERAGEIF($A$2:$A$38,A53,L$2:L$38) -> 1.6666667 | F53: =IFERROR(AVERAGEIF($A$2:$A$38,A53,J$2:J$38),"n/a") -> 2 | G53: =AVERAGEIF($A$2:$A$38,A53,O$2:O$38) -> 0.97222222 | H53: =_xlfn.MINIFS(O$2:O$38,$A$2:$A$38,A53) -> 0.91666667
A54: TC04 | B54: =COUNTIF($A$2:$A$38,A54) -> 3 | C54: =AVERAGEIF($A$2:$A$38,A54,G$2:G$38) -> 2 | D54: =AVERAGEIF($A$2:$A$38,A54,H$2:H$38) -> 2 | E54: =AVERAGEIF($A$2:$A$38,A54,L$2:L$38) -> 2 | F54: =IFERROR(AVERAGEIF($A$2:$A$38,A54,J$2:J$38),"n/a") -> 1 | G54: =AVERAGEIF($A$2:$A$38,A54,O$2:O$38) -> 0.83333333 | H54: =_xlfn.MINIFS(O$2:O$38,$A$2:$A$38,A54) -> 0.83333333
A55: TC05 | B55: =COUNTIF($A$2:$A$38,A55) -> 3 | C55: =AVERAGEIF($A$2:$A$38,A55,G$2:G$38) -> 2 | D55: =AVERAGEIF($A$2:$A$38,A55,H$2:H$38) -> 2 | E55: =AVERAGEIF($A$2:$A$38,A55,L$2:L$38) -> 2 | F55: =IFERROR(AVERAGEIF($A$2:$A$38,A55,J$2:J$38),"n/a") -> 2 | G55: =AVERAGEIF($A$2:$A$38,A55,O$2:O$38) -> 1 | H55: =_xlfn.MINIFS(O$2:O$38,$A$2:$A$38,A55) -> 1
A56: TC06 | B56: =COUNTIF($A$2:$A$38,A56) -> 3 | C56: =AVERAGEIF($A$2:$A$38,A56,G$2:G$38) -> 2 | D56: =AVERAGEIF($A$2:$A$38,A56,H$2:H$38) -> 2 | E56: =AVERAGEIF($A$2:$A$38,A56,L$2:L$38) -> 2 | F56: =IFERROR(AVERAGEIF($A$2:$A$38,A56,J$2:J$38),"n/a") -> 2 | G56: =AVERAGEIF($A$2:$A$38,A56,O$2:O$38) -> 1 | H56: =_xlfn.MINIFS(O$2:O$38,$A$2:$A$38,A56) -> 1
A57: TC07 | B57: =COUNTIF($A$2:$A$38,A57) -> 3 | C57: =AVERAGEIF($A$2:$A$38,A57,G$2:G$38) -> 2 | D57: =AVERAGEIF($A$2:$A$38,A57,H$2:H$38) -> 1 | E57: =AVERAGEIF($A$2:$A$38,A57,L$2:L$38) -> 2 | F57: =IFERROR(AVERAGEIF($A$2:$A$38,A57,J$2:J$38),"n/a") -> 2 | G57: =AVERAGEIF($A$2:$A$38,A57,O$2:O$38) -> 0.91666667 | H57: =_xlfn.MINIFS(O$2:O$38,$A$2:$A$38,A57) -> 0.91666667
A58: TC08 | B58: =COUNTIF($A$2:$A$38,A58) -> 4 | C58: =AVERAGEIF($A$2:$A$38,A58,G$2:G$38) -> 1 | D58: =AVERAGEIF($A$2:$A$38,A58,H$2:H$38) -> 1.75 | E58: =AVERAGEIF($A$2:$A$38,A58,L$2:L$38) -> 0.5 | F58: =IFERROR(AVERAGEIF($A$2:$A$38,A58,J$2:J$38),"n/a") -> 2 | G58: =AVERAGEIF($A$2:$A$38,A58,O$2:O$38) -> 0.72916667 | H58: =_xlfn.MINIFS(O$2:O$38,$A$2:$A$38,A58) -> 0.41666667
A59: TC09 | B59: =COUNTIF($A$2:$A$38,A59) -> 3 | C59: =AVERAGEIF($A$2:$A$38,A59,G$2:G$38) -> 2 | D59: =AVERAGEIF($A$2:$A$38,A59,H$2:H$38) -> 1 | E59: =AVERAGEIF($A$2:$A$38,A59,L$2:L$38) -> 2 | F59: =IFERROR(AVERAGEIF($A$2:$A$38,A59,J$2:J$38),"n/a") -> 2 | G59: =AVERAGEIF($A$2:$A$38,A59,O$2:O$38) -> 0.83333333 | H59: =_xlfn.MINIFS(O$2:O$38,$A$2:$A$38,A59) -> 0.83333333
A60: TC10 | B60: =COUNTIF($A$2:$A$38,A60) -> 3 | C60: =AVERAGEIF($A$2:$A$38,A60,G$2:G$38) -> 2 | D60: =AVERAGEIF($A$2:$A$38,A60,H$2:H$38) -> 1 | E60: =AVERAGEIF($A$2:$A$38,A60,L$2:L$38) -> 1.3333333 | F60: =IFERROR(AVERAGEIF($A$2:$A$38,A60,J$2:J$38),"n/a") -> 1.6666667 | G60: =AVERAGEIF($A$2:$A$38,A60,O$2:O$38) -> 0.83333333 | H60: =_xlfn.MINIFS(O$2:O$38,$A$2:$A$38,A60) -> 0.75
...

Sheet Inter-rater Check
A1: Inter-rater check — AB to score independently
A2: How to use: before looking at the 'AI Quality Scoring' sheet, open each run's ai_output.json (or PR comment) and the ground truth, apply 'Scoring Rules', and type your 0–2 scores in the yellow cells (columns D–I; leave I/R/C blank for TC01/TC12). Agreement updates automatically. Sample: 10 of 37 runs, stratified to include clean, partial, failed and false-positive cases.
A4: Example of the expected format (not part of the sample): TC02 run 1 → D 2, E 2, I 2, R 2, C 2, U 2.
A6: TC | B6: Run | C6: Run ID | D6: AB: D | E6: AB: E | F6: AB: I | G6: AB: R | H6: AB: C | I6: AB: U | J6: AI scorer: D | K6: E | L6: I | M6: R | N6: C | O6: U | P6: Exact matches | Q6: Dimensions scored | R6: Within 1 point
A7: TC02 | B7: 1 | C7: ='AI Quality Scoring'!C5 -> 38404584887 | J7: ='AI Quality Scoring'!G5 -> 2 | K7: ='AI Quality Scoring'!H5 -> 2 | L7: ='AI Quality Scoring'!I5 -> 2 | M7: ='AI Quality Scoring'!J5 -> 2 | N7: ='AI Quality Scoring'!K5 -> 2 | O7: ='AI Quality Scoring'!L5 -> 2 | P7: =IF(AND(ISNUMBER(D7),ISNUMBER(J7)),--(D7=J7),0)+IF(AND(ISNUMBER(E7),ISNUMBER(K7)),--(E7=K7),0)+IF(AND(ISNUMBER(F7),ISNUMBER(L7)),--(F7=L7),0)+IF(AND(ISNUMBER(G7),ISNUMBER(M7)),--(G7=M7),0)+IF(AND(ISNUMBER(H7),ISNUMBER(N7)),--(H7=N7),0)+IF(AND(ISNUMBER(I7),ISNUMBER(O7)),--(I7=O7),0) -> 0 | Q7: =--AND(ISNUMBER(D7),ISNUMBER(J7))+--AND(ISNUMBER(E7),ISNUMBER(K7))+--AND(ISNUMBER(F7),ISNUMBER(L7))+--AND(ISNUMBER(G7),ISNUMBER(M7))+--AND(ISNUMBER(H7),ISNUMBER(N7))+--AND(ISNUMBER(I7),ISNUMBER(O7)) -> 0 | R7: =IF(AND(ISNUMBER(D7),ISNUMBER(J7)),--(ABS(D7-J7)<=1),0)+IF(AND(ISNUMBER(E7),ISNUMBER(K7)),--(ABS(E7-K7)<=1),0)+IF(AND(ISNUMBER(F7),ISNUMBER(L7)),--(ABS(F7-L7)<=1),0)+IF(AND(ISNUMBER(G7),ISNUMBER(M7)),--(ABS(G7-M7)<=1),0)+IF(AND(ISNUMBER(H7),ISNUMBER(N7)),--(ABS(H7-N7)<=1),0)+IF(AND(ISNUMBER(I7),ISNUMBER(O7)),--(ABS(I7-O7)<=1),0) -> 0
A8: TC04 | B8: 2 | C8: ='AI Quality Scoring'!C12 -> 38405031009 | J8: ='AI Quality Scoring'!G12 -> 2 | K8: ='AI Quality Scoring'!H12 -> 2 | L8: ='AI Quality Scoring'!I12 -> 1 | M8: ='AI Quality Scoring'!J12 -> 1 | N8: ='AI Quality Scoring'!K12 -> 2 | O8: ='AI Quality Scoring'!L12 -> 2 | P8: =IF(AND(ISNUMBER(D8),ISNUMBER(J8)),--(D8=J8),0)+IF(AND(ISNUMBER(E8),ISNUMBER(K8)),--(E8=K8),0)+IF(AND(ISNUMBER(F8),ISNUMBER(L8)),--(F8=L8),0)+IF(AND(ISNUMBER(G8),ISNUMBER(M8)),--(G8=M8),0)+IF(AND(ISNUMBER(H8),ISNUMBER(N8)),--(H8=N8),0)+IF(AND(ISNUMBER(I8),ISNUMBER(O8)),--(I8=O8),0) -> 0 | Q8: =--AND(ISNUMBER(D8),ISNUMBER(J8))+--AND(ISNUMBER(E8),ISNUMBER(K8))+--AND(ISNUMBER(F8),ISNUMBER(L8))+--AND(ISNUMBER(G8),ISNUMBER(M8))+--AND(ISNUMBER(H8),ISNUMBER(N8))+--AND(ISNUMBER(I8),ISNUMBER(O8)) -> 0 | R8: =IF(AND(ISNUMBER(D8),ISNUMBER(J8)),--(ABS(D8-J8)<=1),0)+IF(AND(ISNUMBER(E8),ISNUMBER(K8)),--(ABS(E8-K8)<=1),0)+IF(AND(ISNUMBER(F8),ISNUMBER(L8)),--(ABS(F8-L8)<=1),0)+IF(AND(ISNUMBER(G8),ISNUMBER(M8)),--(ABS(G8-M8)<=1),0)+IF(AND(ISNUMBER(H8),ISNUMBER(N8)),--(ABS(H8-N8)<=1),0)+IF(AND(ISNUMBER(I8),ISNUMBER(O8)),--(ABS(I8-O8)<=1),0) -> 0
A9: TC07 | B9: 1 | C9: ='AI Quality Scoring'!C20 -> 38404600206 | J9: ='AI Quality Scoring'!G20 -> 2 | K9: ='AI Quality Scoring'!H20 -> 1 | L9: ='AI Quality Scoring'!I20 -> 2 | M9: ='AI Quality Scoring'!J20 -> 2 | N9: ='AI Quality Scoring'!K20 -> 2 | O9: ='AI Quality Scoring'!L20 -> 2 | P9: =IF(AND(ISNUMBER(D9),ISNUMBER(J9)),--(D9=J9),0)+IF(AND(ISNUMBER(E9),ISNUMBER(K9)),--(E9=K9),0)+IF(AND(ISNUMBER(F9),ISNUMBER(L9)),--(F9=L9),0)+IF(AND(ISNUMBER(G9),ISNUMBER(M9)),--(G9=M9),0)+IF(AND(ISNUMBER(H9),ISNUMBER(N9)),--(H9=N9),0)+IF(AND(ISNUMBER(I9),ISNUMBER(O9)),--(I9=O9),0) -> 0 | Q9: =--AND(ISNUMBER(D9),ISNUMBER(J9))+--AND(ISNUMBER(E9),ISNUMBER(K9))+--AND(ISNUMBER(F9),ISNUMBER(L9))+--AND(ISNUMBER(G9),ISNUMBER(M9))+--AND(ISNUMBER(H9),ISNUMBER(N9))+--AND(ISNUMBER(I9),ISNUMBER(O9)) -> 0 | R9: =IF(AND(ISNUMBER(D9),ISNUMBER(J9)),--(ABS(D9-J9)<=1),0)+IF(AND(ISNUMBER(E9),ISNUMBER(K9)),--(ABS(E9-K9)<=1),0)+IF(AND(ISNUMBER(F9),ISNUMBER(L9)),--(ABS(F9-L9)<=1),0)+IF(AND(ISNUMBER(G9),ISNUMBER(M9)),--(ABS(G9-M9)<=1),0)+IF(AND(ISNUMBER(H9),ISNUMBER(N9)),--(ABS(H9-N9)<=1),0)+IF(AND(ISNUMBER(I9),ISNUMBER(O9)),--(ABS(I9-O9)<=1),0) -> 0
A10: TC08 | B10: 1 | C10: ='AI Quality Scoring'!C23 -> 38404605125 | J10: ='AI Quality Scoring'!G23 -> 0 | K10: ='AI Quality Scoring'!H23 -> 1 | L10: ='AI Quality Scoring'!I23 -> 1 | M10: ='AI Quality Scoring'!J23 -> 2 | N10: ='AI Quality Scoring'!K23 -> 1 | O10: ='AI Quality Scoring'!L23 -> 0 | P10: =IF(AND(ISNUMBER(D10),ISNUMBER(J10)),--(D10=J10),0)+IF(AND(ISNUMBER(E10),ISNUMBER(K10)),--(E10=K10),0)+IF(AND(ISNUMBER(F10),ISNUMBER(L10)),--(F10=L10),0)+IF(AND(ISNUMBER(G10),ISNUMBER(M10)),--(G10=M10),0)+IF(AND(ISNUMBER(H10),ISNUMBER(N10)),--(H10=N10),0)+IF(AND(ISNUMBER(I10),ISNUMBER(O10)),--(I10=O10),0) -> 0 | Q10: =--AND(ISNUMBER(D10),ISNUMBER(J10))+--AND(ISNUMBER(E10),ISNUMBER(K10))+--AND(ISNUMBER(F10),ISNUMBER(L10))+--AND(ISNUMBER(G10),ISNUMBER(M10))+--AND(ISNUMBER(H10),ISNUMBER(N10))+--AND(ISNUMBER(I10),ISNUMBER(O10)) -> 0 | R10: =IF(AND(ISNUMBER(D10),ISNUMBER(J10)),--(ABS(D10-J10)<=1),0)+IF(AND(ISNUMBER(E10),ISNUMBER(K10)),--(ABS(E10-K10)<=1),0)+IF(AND(ISNUMBER(F10),ISNUMBER(L10)),--(ABS(F10-L10)<=1),0)+IF(AND(ISNUMBER(G10),ISNUMBER(M10)),--(ABS(G10-M10)<=1),0)+IF(AND(ISNUMBER(H10),ISNUMBER(N10)),--(ABS(H10-N10)<=1),0)+IF(AND(ISNUMBER(I10),ISNUMBER(O10)),--(ABS(I10-O10)<=1),0) -> 0
A11: TC08 | B11: 4 | C11: ='AI Quality Scoring'!C26 -> 38405218950 | J11: ='AI Quality Scoring'!G26 -> 2 | K11: ='AI Quality Scoring'!H26 -> 2 | L11: ='AI Quality Scoring'!I26 -> 2 | M11: ='AI Quality Scoring'!J26 -> 2 | N11: ='AI Quality Scoring'!K26 -> 2 | O11: ='AI Quality Scoring'!L26 -> 2 | P11: =IF(AND(ISNUMBER(D11),ISNUMBER(J11)),--(D11=J11),0)+IF(AND(ISNUMBER(E11),ISNUMBER(K11)),--(E11=K11),0)+IF(AND(ISNUMBER(F11),ISNUMBER(L11)),--(F11=L11),0)+IF(AND(ISNUMBER(G11),ISNUMBER(M11)),--(G11=M11),0)+IF(AND(ISNUMBER(H11),ISNUMBER(N11)),--(H11=N11),0)+IF(AND(ISNUMBER(I11),ISNUMBER(O11)),--(I11=O11),0) -> 0 | Q11: =--AND(ISNUMBER(D11),ISNUMBER(J11))+--AND(ISNUMBER(E11),ISNUMBER(K11))+--AND(ISNUMBER(F11),ISNUMBER(L11))+--AND(ISNUMBER(G11),ISNUMBER(M11))+--AND(ISNUMBER(H11),ISNUMBER(N11))+--AND(ISNUMBER(I11),ISNUMBER(O11)) -> 0 | R11: =IF(AND(ISNUMBER(D11),ISNUMBER(J11)),--(ABS(D11-J11)<=1),0)+IF(AND(ISNUMBER(E11),ISNUMBER(K11)),--(ABS(E11-K11)<=1),0)+IF(AND(ISNUMBER(F11),ISNUMBER(L11)),--(ABS(F11-L11)<=1),0)+IF(AND(ISNUMBER(G11),ISNUMBER(M11)),--(ABS(G11-M11)<=1),0)+IF(AND(ISNUMBER(H11),ISNUMBER(N11)),--(ABS(H11-N11)<=1),0)+IF(AND(ISNUMBER(I11),ISNUMBER(O11)),--(ABS(I11-O11)<=1),0) -> 0
A12: TC09 | B12: 2 | C12: ='AI Quality Scoring'!C28 -> 38405075984 | J12: ='AI Quality Scoring'!G28 -> 2 | K12: ='AI Quality Scoring'!H28 -> 1 | L12: ='AI Quality Scoring'!I28 -> 1 | M12: ='AI Quality Scoring'!J28 -> 2 | N12: ='AI Quality Scoring'!K28 -> 2 | O12: ='AI Quality Scoring'!L28 -> 2 | P12: =IF(AND(ISNUMBER(D12),ISNUMBER(J12)),--(D12=J12),0)+IF(AND(ISNUMBER(E12),ISNUMBER(K12)),--(E12=K12),0)+IF(AND(ISNUMBER(F12),ISNUMBER(L12)),--(F12=L12),0)+IF(AND(ISNUMBER(G12),ISNUMBER(M12)),--(G12=M12),0)+IF(AND(ISNUMBER(H12),ISNUMBER(N12)),--(H12=N12),0)+IF(AND(ISNUMBER(I12),ISNUMBER(O12)),--(I12=O12),0) -> 0 | Q12: =--AND(ISNUMBER(D12),ISNUMBER(J12))+--AND(ISNUMBER(E12),ISNUMBER(K12))+--AND(ISNUMBER(F12),ISNUMBER(L12))+--AND(ISNUMBER(G12),ISNUMBER(M12))+--AND(ISNUMBER(H12),ISNUMBER(N12))+--AND(ISNUMBER(I12),ISNUMBER(O12)) -> 0 | R12: =IF(AND(ISNUMBER(D12),ISNUMBER(J12)),--(ABS(D12-J12)<=1),0)+IF(AND(ISNUMBER(E12),ISNUMBER(K12)),--(ABS(E12-K12)<=1),0)+IF(AND(ISNUMBER(F12),ISNUMBER(L12)),--(ABS(F12-L12)<=1),0)+IF(AND(ISNUMBER(G12),ISNUMBER(M12)),--(ABS(G12-M12)<=1),0)+IF(AND(ISNUMBER(H12),ISNUMBER(N12)),--(ABS(H12-N12)<=1),0)+IF(AND(ISNUMBER(I12),ISNUMBER(O12)),--(ABS(I12-O12)<=1),0) -> 0
A13: TC10 | B13: 1 | C13: ='AI Quality Scoring'!C30 -> 38404612132 | J13: ='AI Quality Scoring'!G30 -> 2 | K13: ='AI Quality Scoring'!H30 -> 1 | L13: ='AI Quality Scoring'!I30 -> 2 | M13: ='AI Quality Scoring'!J30 -> 1 | N13: ='AI Quality Scoring'!K30 -> 2 | O13: ='AI Quality Scoring'!L30 -> 1 | P13: =IF(AND(ISNUMBER(D13),ISNUMBER(J13)),--(D13=J13),0)+IF(AND(ISNUMBER(E13),ISNUMBER(K13)),--(E13=K13),0)+IF(AND(ISNUMBER(F13),ISNUMBER(L13)),--(F13=L13),0)+IF(AND(ISNUMBER(G13),ISNUMBER(M13)),--(G13=M13),0)+IF(AND(ISNUMBER(H13),ISNUMBER(N13)),--(H13=N13),0)+IF(AND(ISNUMBER(I13),ISNUMBER(O13)),--(I13=O13),0) -> 0 | Q13: =--AND(ISNUMBER(D13),ISNUMBER(J13))+--AND(ISNUMBER(E13),ISNUMBER(K13))+--AND(ISNUMBER(F13),ISNUMBER(L13))+--AND(ISNUMBER(G13),ISNUMBER(M13))+--AND(ISNUMBER(H13),ISNUMBER(N13))+--AND(ISNUMBER(I13),ISNUMBER(O13)) -> 0 | R13: =IF(AND(ISNUMBER(D13),ISNUMBER(J13)),--(ABS(D13-J13)<=1),0)+IF(AND(ISNUMBER(E13),ISNUMBER(K13)),--(ABS(E13-K13)<=1),0)+IF(AND(ISNUMBER(F13),ISNUMBER(L13)),--(ABS(F13-L13)<=1),0)+IF(AND(ISNUMBER(G13),ISNUMBER(M13)),--(ABS(G13-M13)<=1),0)+IF(AND(ISNUMBER(H13),ISNUMBER(N13)),--(ABS(H13-N13)<=1),0)+IF(AND(ISNUMBER(I13),ISNUMBER(O13)),--(ABS(I13-O13)<=1),0) -> 0
A14: TC11 | B14: 3 | C14: ='AI Quality Scoring'!C35 -> 38405200842 | J14: ='AI Quality Scoring'!G35 -> 2 | K14: ='AI Quality Scoring'!H35 -> 2 | L14: ='AI Quality Scoring'!I35 -> 2 | M14: ='AI Quality Scoring'!J35 -> 2 | N14: ='AI Quality Scoring'!K35 -> 2 | O14: ='AI Quality Scoring'!L35 -> 2 | P14: =IF(AND(ISNUMBER(D14),ISNUMBER(J14)),--(D14=J14),0)+IF(AND(ISNUMBER(E14),ISNUMBER(K14)),--(E14=K14),0)+IF(AND(ISNUMBER(F14),ISNUMBER(L14)),--(F14=L14),0)+IF(AND(ISNUMBER(G14),ISNUMBER(M14)),--(G14=M14),0)+IF(AND(ISNUMBER(H14),ISNUMBER(N14)),--(H14=N14),0)+IF(AND(ISNUMBER(I14),ISNUMBER(O14)),--(I14=O14),0) -> 0 | Q14: =--AND(ISNUMBER(D14),ISNUMBER(J14))+--AND(ISNUMBER(E14),ISNUMBER(K14))+--AND(ISNUMBER(F14),ISNUMBER(L14))+--AND(ISNUMBER(G14),ISNUMBER(M14))+--AND(ISNUMBER(H14),ISNUMBER(N14))+--AND(ISNUMBER(I14),ISNUMBER(O14)) -> 0 | R14: =IF(AND(ISNUMBER(D14),ISNUMBER(J14)),--(ABS(D14-J14)<=1),0)+IF(AND(ISNUMBER(E14),ISNUMBER(K14)),--(ABS(E14-K14)<=1),0)+IF(AND(ISNUMBER(F14),ISNUMBER(L14)),--(ABS(F14-L14)<=1),0)+IF(AND(ISNUMBER(G14),ISNUMBER(M14)),--(ABS(G14-M14)<=1),0)+IF(AND(ISNUMBER(H14),ISNUMBER(N14)),--(ABS(H14-N14)<=1),0)+IF(AND(ISNUMBER(I14),ISNUMBER(O14)),--(ABS(I14-O14)<=1),0) -> 0
A15: TC12 | B15: 1 | C15: ='AI Quality Scoring'!C36 -> 38404619147 | J15: ='AI Quality Scoring'!G36 -> 0 | K15: ='AI Quality Scoring'!H36 -> 1 | L15: ='AI Quality Scoring'!I36 -> n/a | M15: ='AI Quality Scoring'!J36 -> n/a | N15: ='AI Quality Scoring'!K36 -> n/a | O15: ='AI Quality Scoring'!L36 -> 0 | P15: =IF(AND(ISNUMBER(D15),ISNUMBER(J15)),--(D15=J15),0)+IF(AND(ISNUMBER(E15),ISNUMBER(K15)),--(E15=K15),0)+IF(AND(ISNUMBER(F15),ISNUMBER(L15)),--(F15=L15),0)+IF(AND(ISNUMBER(G15),ISNUMBER(M15)),--(G15=M15),0)+IF(AND(ISNUMBER(H15),ISNUMBER(N15)),--(H15=N15),0)+IF(AND(ISNUMBER(I15),ISNUMBER(O15)),--(I15=O15),0) -> 0 | Q15: =--AND(ISNUMBER(D15),ISNUMBER(J15))+--AND(ISNUMBER(E15),ISNUMBER(K15))+--AND(ISNUMBER(F15),ISNUMBER(L15))+--AND(ISNUMBER(G15),ISNUMBER(M15))+--AND(ISNUMBER(H15),ISNUMBER(N15))+--AND(ISNUMBER(I15),ISNUMBER(O15)) -> 0 | R15: =IF(AND(ISNUMBER(D15),ISNUMBER(J15)),--(ABS(D15-J15)<=1),0)+IF(AND(ISNUMBER(E15),ISNUMBER(K15)),--(ABS(E15-K15)<=1),0)+IF(AND(ISNUMBER(F15),ISNUMBER(L15)),--(ABS(F15-L15)<=1),0)+IF(AND(ISNUMBER(G15),ISNUMBER(M15)),--(ABS(G15-M15)<=1),0)+IF(AND(ISNUMBER(H15),ISNUMBER(N15)),--(ABS(H15-N15)<=1),0)+IF(AND(ISNUMBER(I15),ISNUMBER(O15)),--(ABS(I15-O15)<=1),0) -> 0
A16: TC12 | B16: 2 | C16: ='AI Quality Scoring'!C37 -> 38405103514 | J16: ='AI Quality Scoring'!G37 -> 1 | K16: ='AI Quality Scoring'!H37 -> 1 | L16: ='AI Quality Scoring'!I37 -> n/a | M16: ='AI Quality Scoring'!J37 -> n/a | N16: ='AI Quality Scoring'!K37 -> n/a | O16: ='AI Quality Scoring'!L37 -> 1 | P16: =IF(AND(ISNUMBER(D16),ISNUMBER(J16)),--(D16=J16),0)+IF(AND(ISNUMBER(E16),ISNUMBER(K16)),--(E16=K16),0)+IF(AND(ISNUMBER(F16),ISNUMBER(L16)),--(F16=L16),0)+IF(AND(ISNUMBER(G16),ISNUMBER(M16)),--(G16=M16),0)+IF(AND(ISNUMBER(H16),ISNUMBER(N16)),--(H16=N16),0)+IF(AND(ISNUMBER(I16),ISNUMBER(O16)),--(I16=O16),0) -> 0 | Q16: =--AND(ISNUMBER(D16),ISNUMBER(J16))+--AND(ISNUMBER(E16),ISNUMBER(K16))+--AND(ISNUMBER(F16),ISNUMBER(L16))+--AND(ISNUMBER(G16),ISNUMBER(M16))+--AND(ISNUMBER(H16),ISNUMBER(N16))+--AND(ISNUMBER(I16),ISNUMBER(O16)) -> 0 | R16: =IF(AND(ISNUMBER(D16),ISNUMBER(J16)),--(ABS(D16-J16)<=1),0)+IF(AND(ISNUMBER(E16),ISNUMBER(K16)),--(ABS(E16-K16)<=1),0)+IF(AND(ISNUMBER(F16),ISNUMBER(L16)),--(ABS(F16-L16)<=1),0)+IF(AND(ISNUMBER(G16),ISNUMBER(M16)),--(ABS(G16-M16)<=1),0)+IF(AND(ISNUMBER(H16),ISNUMBER(N16)),--(ABS(H16-N16)<=1),0)+IF(AND(ISNUMBER(I16),ISNUMBER(O16)),--(ABS(I16-O16)<=1),0) -> 0
A18: Exact agreement | D18: =IF(SUM(Q7:Q16)=0,"not yet scored",SUM(P7:P16)/SUM(Q7:Q16)) -> not yet scored
